Workbook

Sheet Все позиции
A1: КП | B1: Дата КП | C1: Клиент | D1: Менеджер | E1: Статус КП | F1: Срок подачи КП | G1: № строки | H1: Номенклатура | I1: Аналог | J1: Адрес доставки | K1: Количество | L1: Ед. изм. | M1: Цена, ₽ | N1: Цена с НДС, ₽ | O1: Сумма, ₽ | P1: Сумма с НДС, ₽
A2: 00ЦБ-000001 | B2: 46033 | C2: Филиал ООО "АРГОС-Строй"-КЕДР | D2: Шарлаимова Валентина Афанасьевна | E2: Отменено | G2: 1 | H2: Труба фильтр-перфорированная для гидрогеологической скважины ГГС из трубы 57х4 | K2: 190 | L2: м | M2: 8346.5 | N2: 0 | O2: 1585835 | P2: 1934718.7
A3: 00ЦБ-000001 | B3: 46033 | C3: Филиал ООО "АРГОС-Строй"-КЕДР | D3: Шарлаимова Валентина Афанасьевна | E3: Отменено | G3: 2 | H3: Труба 76х4 ГОСТ 8732-78 09Г2С ГОСТ 8731-74 | K3: 0.028 | L3: т | M3: 227008.2 | N3: 0 | O3: 6356.23 | P3: 7754.6
A4: 00ЦБ-000001 | B4: 46033 | C4: Филиал ООО "АРГОС-Строй"-КЕДР | D4: Шарлаимова Валентина Афанасьевна | E4: Отменено | G4: 3 | H4: Труба 168х6 ГОСТ 8732-78 09Г2С ГОСТ 8731-74 | K4: 4.42 | L4: т | M4: 239725.41 | N4: 0 | O4: 1059586.3 | P4: 1292695.3
A5: 00ЦБ-000001 | B5: 46033 | C5: Филиал ООО "АРГОС-Строй"-КЕДР | D5: Шарлаимова Валентина Афанасьевна | E5: Отменено | G5: 4 | H5: Труба 57х4 ГОСТ 8732-78 09Г2С ГОСТ 8731-74 | K5: 3.171 | L5: т | M5: 227008.2 | N5: 0 | O5: 719843 | P5: 878208.46
A6: 00ЦБ-000001 | B6: 46033 | C6: Филиал ООО "АРГОС-Строй"-КЕДР | D6: Шарлаимова Валентина Афанасьевна | E6: Отменено | G6: 5 | H6: Уголок 50х50х5 ГОСТ 8509-93 С345 ГОСТ 27772-2021 KCV(-40)≥34Дж/см2 | K6: 0.009 | L6: т | M6: 99836.07 | N6: 0 | O6: 898.52 | P6: 1096.2
A7: 00ЦБ-000001 | B7: 46033 | C7: Филиал ООО "АРГОС-Строй"-КЕДР | D7: Шарлаимова Валентина Афанасьевна | E7: Отменено | G7: 6 | H7: Труба 108х4 ГОСТ 8732-78 09Г2С ГОСТ 8731-74 | K7: 0.032 | L7: т | M7: 227008.2 | N7: 0 | O7: 7264.26 | P7: 8862.4
A8: 00ЦБ-000001 | B8: 46033 | C8: Филиал ООО "АРГОС-Строй"-КЕДР | D8: Шарлаимова Валентина Афанасьевна | E8: Отменено | G8: 7 | H8: Труба 180х4 ГОСТ 8732-78 09Г2С ГОСТ 8731-74 | I8: Труба г/к 180х6 ГОСТ 8732-78 09Г2С ГОСТ 8731-74 | K8: 0.099 | L8: т | M8: 273122.96 | N8: 0 | O8: 27039.17 | P8: 32987.79
A9: 00ЦБ-000001 | B9: 46033 | C9: Филиал ООО "АРГОС-Строй"-КЕДР | D9: Шарлаимова Валентина Афанасьевна | E9: Отменено | G9: 8 | H9: Труба 180х5,5 ГОСТ 8732-78 09Г2С ГОСТ 8731-74 | I9: Труба г/к 180х6 ГОСТ 8732-78 09Г2С ГОСТ 8731-74 | K9: 0.063 | L9: т | M9: 273122.96 | N9: 0 | O9: 17206.75 | P9: 20992.23
A10: 00ЦБ-000001 | B10: 46033 | C10: Филиал ООО "АРГОС-Строй"-КЕДР | D10: Шарлаимова Валентина Афанасьевна | E10: Отменено | G10: 9 | H10: Лист Б-ПН-НО-5 ГОСТ 19903-2015 С345 ГОСТ 27772-2021 | K10: 0.033 | L10: т | M10: 102569.67 | N10: 0 | O10: 3384.8 | P10: 4129.46
A11: 00ЦБ-000001 | B11: 46033 | C11: Филиал ООО "АРГОС-Строй"-КЕДР | D11: Шарлаимова Валентина Афанасьевна | E11: Отменено | G11: 10 | H11: Арматура 6 А240 ГОСТ 34028-2016 | K11: 0.017 | L11: т | M11: 79631.14 | N11: 0 | O11: 1353.73 | P11: 1651.55
A12: 00ЦБ-000001 | B12: 46033 | C12: Филиал ООО "АРГОС-Строй"-КЕДР | D12: Шарлаимова Валентина Афанасьевна | E12: Отменено | G12: 11 | H12: Уголок 50х50х5 ГОСТ 8509-93 С345 ГОСТ 27772-2021 | K12: 0.015 | L12: т | M12: 99836.07 | N12: 0 | O12: 1497.54 | P12: 1827
A13: 00ЦБ-000001 | B13: 46033 | C13: Филиал ООО "АРГОС-Строй"-КЕДР | D13: Шарлаимова Валентина Афанасьевна | E13: Отменено | G13: 12 | H13: Труба 180х8 ГОСТ 8732-78 09Г2С ГОСТ 8731-74 | K13: 0.079 | L13: т | M13: 273122.96 | N13: 0 | O13: 21576.71 | P13: 26323.59
A14: 00ЦБ-000001 | B14: 46033 | C14: Филиал ООО "АРГОС-Строй"-КЕДР | D14: Шарлаимова Валентина Афанасьевна | E14: Отменено | G14: 13 | H14: Круг 58 ГОСТ 2590-2006 С345 ГОСТ 27772-2021 | K14: 0.042 | L14: т | M14: 110532.79 | N14: 0 | O14: 4642.38 | P14: 5663.7
A15: 00ЦБ-000001 | B15: 46033 | C15: Филиал ООО "АРГОС-Строй"-КЕДР | D15: Шарлаимова Валентина Афанасьевна | E15: Отменено | G15: 14 | H15: Лист Б-ПН-НО-3 ГОСТ 19903-2015 С345 ГОСТ 27772-2021 | K15: 0.011 | L15: т | M15: 99836.07 | N15: 0 | O15: 1098.2 | P15: 1339.8
A16: 00ЦБ-000001 | B16: 46033 | C16: Филиал ООО "АРГОС-Строй"-КЕДР | D16: Шарлаимова Валентина Афанасьевна | E16: Отменено | G16: 15 | H16: Пластина резиновая 1Ф-1-ТМКЩ-С-5 ГОСТ 7338-90 | K16: 56 | L16: шт | M16: 5968.77 | N16: 0 | O16: 334251.12 | P16: 407786.37
A17: 00ЦБ-000029 | B17: 46034 | C17: Филиал ООО "Аргос-Строй" Прометей | D17: Шарлаимова Валентина Афанасьевна | E17: Отменено | G17: 1 | H17: Задвижка стальная клиновая с выдвижным шпинделем, фланцевая (исп. F-E) из стали 20ГЛ, ХЛ1 DN80 PN250 с ручным управлением в комплекте с ответными флан | I17: Задвижка клиноваяс 31лс45нж Ду80 Ру250 ЗКЛ 080.250.01.Ф исп.RTG 16,5 по ASME, ст.20ГЛ, класс герм. А по ГОСТ 9544-2015 | K17: 1 | L17: шт | M17: 300401.33 | N17: 0 | O17: 300401.33 | P17: 366489.62
A18: 00ЦБ-000029 | B18: 46034 | C18: Филиал ООО "Аргос-Строй" Прометей | D18: Шарлаимова Валентина Афанасьевна | E18: Отменено | G18: 2 | H18: Задвижка стальная клиновая с выдвижным шпинделем, фланцевая (исп. F-E) из стали 20ГЛ, ХЛ1 DN150 PN250 с ручным управлением в комплекте с ответными фла | K18: 4 | L18: шт | M18: 0 | N18: 0 | O18: 0 | P18: 0
A19: 00ЦБ-000029 | B19: 46034 | C19: Филиал ООО "Аргос-Строй" Прометей | D19: Шарлаимова Валентина Афанасьевна | E19: Отменено | G19: 3 | H19: Затвор(клапан) обратный фланцевый из стали 20ГЛ в комплекте с ответными фланцами из стали 20А, ХЛ1 DN150 PN250 с прокладками и крепежом с приварными к | K19: 4 | L19: шт | M19: 0 | N19: 0 | O19: 0 | P19: 0
A20: 00ЦБ-000029 | B20: 46034 | C20: Филиал ООО "Аргос-Строй" Прометей | D20: Шарлаимова Валентина Афанасьевна | E20: Отменено | G20: 4 | H20: Трубы стальные бесшовные из стали 20А с внутренним антикоррозионным двухслойным порошковым эпоксидным покрытием ПЭП7150, Ø273х20-20А | I20: Труба г/к 273х20 ст13ХФА с внутренним однослойным эпоксидным покрытием по ТУ 1390-025-39929189-2020 (изм.1) ТРЭПП- ТР-90 МА (температура эксплуатации | K20: 124.8 | L20: т | M20: 65299.02 | N20: 0 | O20: 8149317.7 | P20: 9942167.6
A21: 00ЦБ-000029 | B21: 46034 | C21: Филиал ООО "Аргос-Строй" Прометей | D21: Шарлаимова Валентина Афанасьевна | E21: Отменено | G21: 5 | H21: Трубы стальные бесшовные из стали 20А с внутренним антикоррозионным двухслойным порошковым эпоксидным покрытием ПЭП7150, Ø168х14-20А | I21: Труба г/к 168х14 ст13ХФА с внутренним однослойным эпоксидным покрытием по ТУ 1390-025-39929189-2020 (изм.1) ТРЭПП- ТР-90 МА (температура эксплуатации | K21: 53.7 | L21: т | M21: 30028.67 | N21: 0 | O21: 1612539.6 | P21: 1967298.3
A22: 00ЦБ-000029 | B22: 46034 | C22: Филиал ООО "Аргос-Строй" Прометей | D22: Шарлаимова Валентина Афанасьевна | E22: Отменено | G22: 6 | H22: Трубы стальные бесшовные из стали 20А с внутренним антикоррозионным двухслойным порошковым эпоксидным покрытием ПЭП7150, Ø80х10-20А | I22: Труба г/к 89х10 ст13ХФА с внутренним однослойным эпоксидным покрытием по ТУ 1390-025-39929189-2020 (изм.1) ТРЭПП- ТР-90 МА (температура эксплуатации д | K22: 19.48 | L22: т | M22: 348023.78 | N22: 0 | O22: 6779503.2 | P22: 8270993.9
A23: 00ЦБ-000029 | B23: 46034 | C23: Филиал ООО "Аргос-Строй" Прометей | D23: Шарлаимова Валентина Афанасьевна | E23: Отменено | G23: 7 | H23: Отвод крутоизогнутый бесшовный приварной из стали 20А 90 - 273х20 - 20А | I23: Отвод 90 273х19 ст.13хфа ТУ с геометрией по ГОСТ 17375-01 | K23: 2 | L23: шт | M23: 66979.31 | N23: 0 | O23: 133958.62 | P23: 163429.52
A24: 00ЦБ-000029 | B24: 46034 | C24: Филиал ООО "Аргос-Строй" Прометей | D24: Шарлаимова Валентина Афанасьевна | E24: Отменено | G24: 8 | H24: Отвод крутоизогнутый бесшовный приварной из стали 20А 90 - 168х14 - 20А | I24: Отвод 90 168х14 ст.13хфа ТУ с геометрией по ГОСТ 17375-01 | K24: 13 | L24: шт | M24: 18855.95 | N24: 0 | O24: 245127.35 | P24: 299055.37
A25: 00ЦБ-000029 | B25: 46034 | C25: Филиал ООО "Аргос-Строй" Прометей | D25: Шарлаимова Валентина Афанасьевна | E25: Отменено | G25: 9 | H25: Переход концентрический бесшовный приварной из стали 20А К 168х14-133х18 - 20А | K25: 3 | L25: шт | M25: 0 | N25: 0 | O25: 0 | P25: 0
A26: 00ЦБ-000029 | B26: 46034 | C26: Филиал ООО "Аргос-Строй" Прометей | D26: Шарлаимова Валентина Афанасьевна | E26: Отменено | G26: 10 | H26: Переход концентрический бесшовный приварной из стали 20А К 273х20-168х14 - 20А | K26: 7 | L26: шт | M26: 0 | N26: 0 | O26: 0 | P26: 0
A27: 00ЦБ-000029 | B27: 46034 | C27: Филиал ООО "Аргос-Строй" Прометей | D27: Шарлаимова Валентина Афанасьевна | E27: Отменено | G27: 11 | H27: Тройник бесшовный приварной из стали 20А 273х20-168х14 | K27: 3 | L27: шт | M27: 0 | N27: 0 | O27: 0 | P27: 0
A28: 00ЦБ-000029 | B28: 46034 | C28: Филиал ООО "Аргос-Строй" Прометей | D28: Шарлаимова Валентина Афанасьевна | E28: Отменено | G28: 12 | H28: Опоры 273-КХ-А11 | K28: 4 | L28: шт | M28: 4789.54 | N28: 0 | O28: 19158.16 | P28: 23372.96
A29: 00ЦБ-000029 | B29: 46034 | C29: Филиал ООО "Аргос-Строй" Прометей | D29: Шарлаимова Валентина Афанасьевна | E29: Отменено | G29: 13 | H29: Опоры 159-КХ-А11 | K29: 4 | L29: шт | M29: 2266.77 | N29: 0 | O29: 9067.08 | P29: 11061.84
A30: 00ЦБ-000029 | B30: 46034 | C30: Филиал ООО "Аргос-Строй" Прометей | D30: Шарлаимова Валентина Афанасьевна | E30: Отменено | G30: 14 | H30: Втулка внутренней защиты сварного шва трубопровода CPS 273х20 | K30: 13 | L30: шт | M30: 0 | N30: 0 | O30: 0 | P30: 0
A31: 00ЦБ-000029 | B31: 46034 | C31: Филиал ООО "Аргос-Строй" Прометей | D31: Шарлаимова Валентина Афанасьевна | E31: Отменено | G31: 15 | H31: Втулка внутренней защиты сварного шва трубопровода CPS 168х14 | K31: 30 | L31: шт | M31: 0 | N31: 0 | O31: 0 | P31: 0
A32: 00ЦБ-000029 | B32: 46034 | C32: Филиал ООО "Аргос-Строй" Прометей | D32: Шарлаимова Валентина Афанасьевна | E32: Отменено | G32: 16 | H32: Втулка внутренней защиты сварного шва трубопровода CPS 89х6 | K32: 23 | L32: шт | M32: 0 | N32: 0 | O32: 0 | P32: 0
A33: 00ЦБ-000029 | B33: 46034 | C33: Филиал ООО "Аргос-Строй" Прометей | D33: Шарлаимова Валентина Афанасьевна | E33: Отменено | G33: 17 | H33: Спецдеталь СД.5 ПНГ-012-22-Р-ТХ.2-ОЛ-001 | K33: 3 | L33: шт | M33: 0 | N33: 0 | O33: 0 | P33: 0
A34: 00ЦБ-000029 | B34: 46034 | C34: Филиал ООО "Аргос-Строй" Прометей | D34: Шарлаимова Валентина Афанасьевна | E34: Отменено | G34: 18 | H34: Спецдеталь СД.6 ПНГ-012-22-Р-ТХ.2-ОЛ-001 | K34: 4 | L34: шт | M34: 0 | N34: 0 | O34: 0 | P34: 0
A35: 00ЦБ-000029 | B35: 46034 | C35: Филиал ООО "Аргос-Строй" Прометей | D35: Шарлаимова Валентина Афанасьевна | E35: Отменено | G35: 19 | H35: Спецдеталь СД.7 ПНГ-012-22-Р-ТХ.2-ОЛ-001 | K35: 4 | L35: шт | M35: 0 | N35: 0 | O35: 0 | P35: 0
A36: 00ЦБ-000029 | B36: 46034 | C36: Филиал ООО "Аргос-Строй" Прометей | D36: Шарлаимова Валентина Афанасьевна | E36: Отменено | G36: 20 | H36: Спецдеталь СД.8 ПНГ-012-22-Р-ТХ.2-ОЛ-001 | K36: 1 | L36: шт | M36: 0 | N36: 0 | O36: 0 | P36: 0
... A42: 00ЦБ-000004 | B42: 46035 | C42: Филиал ООО "АРГОС-Строй"-КЕДР | D42: Шарлаимова Валентина Афанасьевна | E42: Отменено | G42: 4 | H42: Трубопоршневая установка | K42: 1 | L42: комп | M42: 56550000 | N42: 0 | O42: 56550000 | P42: 68991000
A43: 00ЦБ-000004 | B43: 46035 | C43: Филиал ООО "АРГОС-Строй"-КЕДР | D43: Шарлаимова Валентина Афанасьевна | E43: Отменено | G43: 5 | H43: Задвижка клиновая фланцевая Ду 200 | I43: Задвижка клиновая литая с выдвижным шпинделем фланцевая (исп. F) ручная 30лс76нж DN 200 PN 6,3 МПа ХЛ1, корпус ст. 20ГЛ, класс герметичности «А» по ГО | K43: 3 | L43: шт | M43: 413844.27 | N43: 0 | O43: 1241532.8 | P43: 1514670
A44: 00ЦБ-000004 | B44: 46035 | C44: Филиал ООО "АРГОС-Строй"-КЕДР | D44: Шарлаимова Валентина Афанасьевна | E44: Отменено | G44: 6 | H44: Задвижка клиновая фланцевая Ду 200 с контролем протечек | I44: Задвижка клиновая литая с выдвижным шпинделем фланцевая (исп. F) ручная 30лс76нж DN 200 PN 6,3 МПа ХЛ1, корпус ст. 20ГЛ, класс герметичности «А» по ГО | K44: 1 | L44: шт | M44: 413844.27 | N44: 0 | O44: 413844.27 | P44: 504890.01
A45: 00ЦБ-000004 | B45: 46035 | C45: Филиал ООО "АРГОС-Строй"-КЕДР | D45: Шарлаимова Валентина Афанасьевна | E45: Отменено | G45: 7 | H45: Кран шаровой Ду15-Ду50 | K45: 18 | L45: шт | M45: 41165.73 | N45: 0 | O45: 740983.14 | P45: 903999.43
...

Sheet Со сроком подачи КП
A1: КП | B1: Дата КП | C1: Клиент | D1: Менеджер | E1: Статус КП | F1: Срок подачи КП | G1: № строки | H1: Номенклатура | I1: Аналог | J1: Адрес доставки | K1: Количество | L1: Ед. изм. | M1: Цена, ₽ | N1: Цена с НДС, ₽ | O1: Сумма, ₽ | P1: Сумма с НДС, ₽
A2: 00ЦБ-000455 | B2: 46204 | C2: Филиал ООО "АРГОС-Строй"-КЕДР | D2: Шарлаимова Валентина Афанасьевна | E2: Отменено | F2: 46218 | G2: 1 | H2: Выключатель однополюсный Viva, 2 модуль, белый, код 45021 | K2: 39 | L2: шт | M2: 1010.61 | N2: 0 | O2: 39413.79 | P2: 48084.82
A3: 00ЦБ-000455 | B3: 46204 | C3: Филиал ООО "АРГОС-Строй"-КЕДР | D3: Шарлаимова Валентина Афанасьевна | E3: Отменено | F3: 46218 | G3: 2 | H3: Выключатель однополюсный, одноклавишный, настенный, IP66, номинальный ток-20А, номинальное напряжение-250 | K3: 5 | L3: шт | M3: 3358.91 | N3: 0 | O3: 16794.55 | P3: 20489.35
A4: 00ЦБ-000455 | B4: 46204 | C4: Филиал ООО "АРГОС-Строй"-КЕДР | D4: Шарлаимова Валентина Афанасьевна | E4: Отменено | F4: 46218 | G4: 3 | H4: Заглушка на 1 модуль, Viva, белая арт.45016 | K4: 11 | L4: шт | M4: 67.97 | N4: 0 | O4: 747.67 | P4: 912.16
A5: 00ЦБ-000455 | B5: 46204 | C5: Филиал ООО "АРГОС-Строй"-КЕДР | D5: Шарлаимова Валентина Афанасьевна | E5: Отменено | F5: 46218 | G5: 4 | H5: Изолятор 2РС для наконечника, для кабелей сечением 4-6 мм2 | K5: 30 | L5: шт | M5: 10.14 | N5: 0 | O5: 304.2 | P5: 371.12
A6: 00ЦБ-000455 | B6: 46204 | C6: Филиал ООО "АРГОС-Строй"-КЕДР | D6: Шарлаимова Валентина Афанасьевна | E6: Отменено | F6: 46218 | G6: 5 | H6: Изолятор для наконечников по типу 2PD, для кабелей сечением 10 мм2 | K6: 40 | L6: шт | M6: 14.18 | N6: 0 | O6: 567.2 | P6: 691.98
A7: 00ЦБ-000455 | B7: 46204 | C7: Филиал ООО "АРГОС-Строй"-КЕДР | D7: Шарлаимова Валентина Афанасьевна | E7: Отменено | F7: 46218 | G7: 6 | H7: Изолятор для наконечников по типу 2РВ, для кабелей сечением 2,5 мм2 | K7: 145 | L7: шт | M7: 6.26 | N7: 0 | O7: 907.7 | P7: 1107.39
A8: 00ЦБ-000455 | B8: 46204 | C8: Филиал ООО "АРГОС-Строй"-КЕДР | D8: Шарлаимова Валентина Афанасьевна | E8: Отменено | F8: 46218 | G8: 7 | H8: Изолятор для наконечников по типу 2РС, для кабелей сечением 4-6 мм2 | K8: 115 | L8: шт | M8: 10.14 | N8: 0 | O8: 1166.1 | P8: 1422.64
A9: 00ЦБ-000455 | B9: 46204 | C9: Филиал ООО "АРГОС-Строй"-КЕДР | D9: Шарлаимова Валентина Афанасьевна | E9: Отменено | F9: 46218 | G9: 8 | H9: Кабельный ввод для коробок по типу 305315.001 | K9: 9 | L9: шт | M9: 262.4 | N9: 0 | O9: 2361.6 | P9: 2881.15
A10: 00ЦБ-000455 | B10: 46204 | C10: Филиал ООО "АРГОС-Строй"-КЕДР | D10: Шарлаимова Валентина Афанасьевна | E10: Отменено | F10: 46218 | G10: 9 | H10: Клеммник винтовой по типу TU150-2-GY для кабеля сечением 150 мм2 | K10: 20 | L10: шт | M10: 2141.95 | N10: 0 | O10: 42839 | P10: 52263.58
A11: 00ЦБ-000455 | B11: 46204 | C11: Филиал ООО "АРГОС-Строй"-КЕДР | D11: Шарлаимова Валентина Афанасьевна | E11: Отменено | F11: 46218 | G11: 10 | H11: Клеммник винтовой по типу TU240-2-GY для кабеля сечением 240 мм2 | K11: 50 | L11: шт | M11: 3396.8 | N11: 0 | O11: 169840 | P11: 207204.8
A12: 00ЦБ-000455 | B12: 46204 | C12: Филиал ООО "АРГОС-Строй"-КЕДР | D12: Шарлаимова Валентина Афанасьевна | E12: Отменено | F12: 46218 | G12: 11 | H12: Клеммник винтовой по типу TU50-2-BU для кабеля сечением 16-70 мм2, синий | K12: 20 | L12: шт | M12: 546.98 | N12: 0 | O12: 10939.6 | P12: 13346.31
A13: 00ЦБ-000455 | B13: 46204 | C13: Филиал ООО "АРГОС-Строй"-КЕДР | D13: Шарлаимова Валентина Афанасьевна | E13: Отменено | F13: 46218 | G13: 12 | H13: Клеммник винтовой по типу TU50-2-GY для кабеля сечением 16-70 мм2, серый | K13: 20 | L13: шт | M13: 546.98 | N13: 0 | O13: 10939.6 | P13: 13346.31
... A139: 00ЦБ-000482 | B139: 46212 | C139: Филиал ООО "Аргос-Строй" Прометей | D139: Шарлаимова Валентина Афанасьевна | E139: Отменено | F139: 46218 | G139: 2 | H139: Гайка М30 ГОСТ ISO 4032-2014 | K139: 40 | L139: шт | M139: 66.83 | N139: 0 | O139: 2673.2 | P139: 3261.3
A140: 00ЦБ-000482 | B140: 46212 | C140: Филиал ООО "Аргос-Строй" Прометей | D140: Шарлаимова Валентина Афанасьевна | E140: Отменено | F140: 46218 | G140: 3 | H140: Мачта прожекторная ВГН-16 02-3647-Р455-С027-ЭС.ОЛ4 | I140: Мачта МГФ-16-I-СП-2,1х1,4-МО-4-ОП2(09Г2С,Г\Ц) | K140: 1 | L140: шт | M140: 636100.83 | N140: 0 | O140: 636100.83 | P140: 776043.01
A141: 00ЦБ-000482 | B141: 46212 | C141: Филиал ООО "Аргос-Строй" Прометей | D141: Шарлаимова Валентина Афанасьевна | E141: Отменено | F141: 46218 | G141: 4 | H141: Опора освещения ОГКС-10,5 02-3647-Р455-С027-ЭС.ОЛ3 | I141: Опора ОГКСкл-10,5(100/225-4) фл.К400-мц 4х32-300 | K141: 2 | L141: шт | M141: 102963.73 | N141: 0 | O141: 205927.46 | P141: 251231.5
A142: 00ЦБ-000482 | B142: 46212 | C142: Филиал ООО "Аргос-Строй" Прометей | D142: Шарлаимова Валентина Афанасьевна | E142: Отменено | F142: 46218 | G142: 5 | H142: Шайба 12 ГОСТ 11371-78 | K142: 192 | L142: шт | M142: 2.2 | N142: 0 | O142: 422.4 | P142: 515.33
A143: 00ЦБ-000482 | B143: 46212 | C143: Филиал ООО "Аргос-Строй" Прометей | D143: Шарлаимова Валентина Афанасьевна | E143: Отменено | F143: 46218 | G143: 6 | H143: Шайба 30 ГОСТ 11371-78 | K143: 40 | L143: шт | M143: 15.49 | N143: 0 | O143: 619.6 | P143: 755.91
A144: 00ЦБ-000483 | B144: 46212 | C144: Филиал ООО "АРГОС-Строй"-КЕДР | D144: Шарлаимова Валентина Афанасьевна | E144: Отменено | F144: 46227 | G144: 1 | H144: Изолятор 2РС для наконечника, для кабелей сечением 4-6 мм2 | K144: 70 | L144: шт | M144: 6.4 | N144: 7.81 | O144: 448 | P144: 546.56
A145: 00ЦБ-000483 | B145: 46212 | C145: Филиал ООО "АРГОС-Строй"-КЕДР | D145: Шарлаимова Валентина Афанасьевна | E145: Отменено | F145: 46227 | G145: 2 | H145: Коробка концевая РТВ401-ИС 2 ExeIIT6 | I145: Коробка соединительная РТВ 401-0/0-ИС | K145: 4 | L145: комп | M145: 7150 | N145: 8723 | O145: 28600 | P145: 34892
A146: 00ЦБ-000483 | B146: 46212 | C146: Филиал ООО "АРГОС-Строй"-КЕДР | D146: Шарлаимова Валентина Афанасьевна | E146: Отменено | F146: 46227 | G146: 3 | H146: Коробка соединительная РТВ401 1Б/02 ExeIIT6 | I146: Коробка соединительная РТВ 401-1Б/0 | K146: 4 | L146: комп | M146: 5750 | N146: 7015 | O146: 23000 | P146: 28060
A147: 00ЦБ-000483 | B147: 46212 | C147: Филиал ООО "АРГОС-Строй"-КЕДР | D147: Шарлаимова Валентина Афанасьевна | E147: Отменено | F147: 46227 | G147: 4 | H147: Лента нагревательная 15НТР2-ВР | K147: 44 | L147: м | M147: 487 | N147: 594.14 | O147: 21428 | P147: 26142.16
A148: 00ЦБ-000483 | B148: 46212 | C148: Филиал ООО "АРГОС-Строй"-КЕДР | D148: Шарлаимова Валентина Афанасьевна | E148: Отменено | F148: 46227 | G148: 5 | H148: Маркировка для кабеля квадрат 55/55 CIC55554SQW DKC | K148: 448 | L148: шт | M148: 11 | N148: 13.42 | O148: 4928 | P148: 6012.16
A149: 00ЦБ-000483 | B149: 46212 | C149: Филиал ООО "АРГОС-Строй"-КЕДР | D149: Шарлаимова Валентина Афанасьевна | E149: Отменено | F149: 46227 | G149: 6 | H149: Маркировка для кабеля круг D 55 CIC55554CIW DKC | K149: 96 | L149: шт | M149: 11 | N149: 13.42 | O149: 1056 | P149: 1288.32
A150: 00ЦБ-000483 | B150: 46212 | C150: Филиал ООО "АРГОС-Строй"-КЕДР | D150: Шарлаимова Валентина Афанасьевна | E150: Отменено | F150: 46227 | G150: 7 | H150: Маркировка для кабеля треугольник 58/55 CIC58554TRW DKC | K150: 160 | L150: шт | M150: 11 | N150: 13.42 | O150: 1760 | P150: 2147.2
A151: 00ЦБ-000483 | B151: 46212 | C151: Филиал ООО "АРГОС-Строй"-КЕДР | D151: Шарлаимова Валентина Афанасьевна | E151: Отменено | F151: 46227 | G151: 8 | H151: Наконечник кабельный 2СТ6 DKC | K151: 70 | L151: шт | M151: 12 | N151: 14.64 | O151: 840 | P151: 1024.8
A152: 00ЦБ-000485 | B152: 46212 | C152: Филиал ООО "АРГОС-Строй"-КЕДР | D152: Шарлаимова Валентина Афанасьевна | E152: Отменено | F152: 46217 | G152: 1 | H152: Грунт-эмаль СБЭ-111 "Унипол" марка АМ RAL - 7004 ТУ 2313-001-92638584-2011 | I152: Эмаль СБЭ-111 "УНИПОЛ" марка AM (RAL 7004) | K152: 2036.16 | L152: кг | M152: 974.4 | N152: 0 | O152: 1984034.3 | P152: 2420521.9
A153: 00ЦБ-000487 | B153: 46212 | C153: Филиал ООО "Аргос-Строй" Прометей | D153: Шарлаимова Валентина Афанасьевна | E153: Отменено | F153: 46213 | G153: 1 | H153: Профлист С21-1000-0,7 RAL 9016 в комплекте с крепежным элементом | K153: 648 | L153: м2 | M153: 0 | N153: 0 | O153: 0 | P153: 0
A154: 00ЦБ-000484 | B154: 46212 | C154: Филиал ООО "Аргос-Строй" Прометей | D154: Шарлаимова Валентина Афанасьевна | E154: Отменено | F154: 46219 | G154: 1 | H154: Грунт-эмаль "Олиспринт-ФА" марка Б белая Pantone White | I154: Грунт-эмаль "Олиспринт-ФА" марка Б белая | K154: 40 | L154: кг | M154: 897 | N154: 1094.34 | O154: 35880 | P154: 43773.6
A155: 00ЦБ-000484 | B155: 46212 | C155: Филиал ООО "Аргос-Строй" Прометей | D155: Шарлаимова Валентина Афанасьевна | E155: Отменено | F155: 46219 | G155: 2 | H155: Грунт-эмаль "Олиспринт-ФА" марка Б красная Pantone 186С | I155: Грунт-эмаль "Олиспринт-ФА" марка Б красная | K155: 40 | L155: кг | M155: 897 | N155: 1094.34 | O155: 35880 | P155: 43773.6
A156: 00ЦБ-000484 | B156: 46212 | C156: Филиал ООО "Аргос-Строй" Прометей | D156: Шарлаимова Валентина Афанасьевна | E156: Отменено | F156: 46219 | G156: 3 | H156: Опора 114-КХ-170-Ст20 ОСТ 36-146-88 | K156: 4 | L156: шт | M156: 1825.34 | N156: 2226.92 | O156: 7301.36 | P156: 8907.66
A157: 00ЦБ-000490 | B157: 46212 | C157: Филиал ООО "Аргос-Строй" Прометей | D157: Шарлаимова Валентина Афанасьевна | E157: Отменено | F157: 46218 | G157: 1 | H157: Полка кабельная, l=250 мм, S=2,0 горячее цинкование, УХЛ1 | K157: 285 | L157: шт | M157: 118.59 | N157: 0 | O157: 33798.15 | P157: 41233.74
A158: 00ЦБ-000490 | B158: 46212 | C158: Филиал ООО "Аргос-Строй" Прометей | D158: Шарлаимова Валентина Афанасьевна | E158: Отменено | F158: 46218 | G158: 2 | H158: Полка кабельная, l=450 мм, S=2,0 горячее цинкование, УХЛ1 | K158: 1455 | L158: шт | M158: 208.35 | N158: 0 | O158: 303149.25 | P158: 369842.09
A159: 00ЦБ-000490 | B159: 46212 | C159: Филиал ООО "Аргос-Строй" Прометей | D159: Шарлаимова Валентина Афанасьевна | E159: Отменено | F159: 46218 | G159: 3 | H159: Стойка кабельная горячеоцинкованная (ГЦ) Н=400мм | K159: 57 | L159: шт | M159: 238.69 | N159: 0 | O159: 13605.33 | P159: 16598.5
A160: 00ЦБ-000490 | B160: 46212 | C160: Филиал ООО "Аргос-Строй" Прометей | D160: Шарлаимова Валентина Афанасьевна | E160: Отменено | F160: 46218 | G160: 4 | H160: Стойка кабельная горячеоцинкованная (ГЦ) Н=600мм ширина 60 мм, глубина 26 мм, толщина металла 2,5 мм | K160: 102 | L160: шт | M160: 432.63 | N160: 0 | O160: 44128.26 | P160: 53836.48
A161: 00ЦБ-000490 | B161: 46212 | C161: Филиал ООО "Аргос-Строй" Прометей | D161: Шарлаимова Валентина Афанасьевна | E161: Отменено | F161: 46218 | G161: 5 | H161: Стойка кабельная горячеоцинкованная (ГЦ) Н=800мм | K161: 343 | L161: шт | M161: 531.09 | N161: 0 | O161: 182163.87 | P161: 222239.92
A162: 00ЦБ-000489 | B162: 46212 | C162: Филиал ООО "Аргос-Строй" Прометей | D162: Шарлаимова Валентина Афанасьевна | E162: Отменено | F162: 46220 | G162: 1 | H162: Отвод 90-1,5DN - 168х16(168х14)-250-Сталь 20А ТУ 14-1-5598-2011 | K162: 2 | L162: шт | M162: 52745.9 | N162: 65835 | O162: 105491.8 | P162: 128700
A163: 00ЦБ-000489 | B163: 46212 | C163: Филиал ООО "Аргос-Строй" Прометей | D163: Шарлаимова Валентина Афанасьевна | E163: Отменено | F163: 46220 | G163: 2 | H163: Отвод 90-1,5DN - 219х20(219х18)-250-Сталь 20А ТУ 14-1-5598-2011 | K163: 11 | L163: шт | M163: 63614.76 | N163: 79401 | O163: 699762.36 | P163: 853710.08
A164: 00ЦБ-000489 | B164: 46212 | C164: Филиал ООО "Аргос-Строй" Прометей | D164: Шарлаимова Валентина Афанасьевна | E164: Отменено | F164: 46220 | G164: 3 | H164: Отвод 90-1,5DN - 273х24(273х22)-250-Сталь 20А ТУ 14-1-5598-2011 | K164: 14 | L164: шт | M164: 81516.4 | N164: 101745 | O164: 1141229.6 | P164: 1392300.1
A165: 00ЦБ-000489 | B165: 46212 | C165: Филиал ООО "Аргос-Строй" Прометей | D165: Шарлаимова Валентина Афанасьевна | E165: Отменено | F165: 46220 | G165: 4 | H165: Переход ПШ К-219х20(219х18)-168х16(168х14)-250-Сталь 20А ТУ 14-1-5598-2011 | K165: 3 | L165: шт | M165: 72672.6 | N165: 90706.59 | O165: 218017.8 | P165: 265981.72
...

Sheet Свод по номенклатуре
A1: Номенклатура | B1: Ед. изм. | C1: Строк в КП | D1: Количество, всего | E1: Сумма с НДС, всего, ₽ | F1: Строк в КП со сроком подачи | G1: Есть в КП со сроком подачи
A2: "Емкость канализационная для бытовых стоков V=25 м3 в комплекте с КНС (поз. 15)" | B2: комп | C2: =COUNTIFS('Все позиции'!$H$2:$H$10401,A2,'Все позиции'!$L$2:$L$10401,B2) -> 1 | D2: =SUMIFS('Все позиции'!$K$2:$K$10401,'Все позиции'!$H$2:$H$10401,A2,'Все позиции'!$L$2:$L$10401,B2) -> 1 | E2: =SUMIFS('Все позиции'!$P$2:$P$10401,'Все позиции'!$H$2:$H$10401,A2,'Все позиции'!$L$2:$L$10401,B2) -> 0 | F2: =COUNTIFS('Все позиции'!$H$2:$H$10401,A2,'Все позиции'!$L$2:$L$10401,B2,'Все позиции'!$F$2:$F$10401,"<>") -> 1 | G2: =IF(F2>0,"да","нет") -> да
A3: "Емкость канализационная для бытовых стоков V=25 м3 в комплекте с КНС (поз. 15)2" | B3: комп | C3: =COUNTIFS('Все позиции'!$H$2:$H$10401,A3,'Все позиции'!$L$2:$L$10401,B3) -> 1 | D3: =SUMIFS('Все позиции'!$K$2:$K$10401,'Все позиции'!$H$2:$H$10401,A3,'Все позиции'!$L$2:$L$10401,B3) -> 1 | E3: =SUMIFS('Все позиции'!$P$2:$P$10401,'Все позиции'!$H$2:$H$10401,A3,'Все позиции'!$L$2:$L$10401,B3) -> 0 | F3: =COUNTIFS('Все позиции'!$H$2:$H$10401,A3,'Все позиции'!$L$2:$L$10401,B3,'Все позиции'!$F$2:$F$10401,"<>") -> 1 | G3: =IF(F3>0,"да","нет") -> да
A4: 0034.4213, Предохранительные: плавкая вставка; быстрый; 250 мА; 125 ВАС; РСВ, ТНТ (chipdip) | B4: шт | C4: =COUNTIFS('Все позиции'!$H$2:$H$10401,A4,'Все позиции'!$L$2:$L$10401,B4) -> 1 | D4: =SUMIFS('Все позиции'!$K$2:$K$10401,'Все позиции'!$H$2:$H$10401,A4,'Все позиции'!$L$2:$L$10401,B4) -> 300 | E4: =SUMIFS('Все позиции'!$P$2:$P$10401,'Все позиции'!$H$2:$H$10401,A4,'Все позиции'!$L$2:$L$10401,B4) -> 79945.38 | F4: =COUNTIFS('Все позиции'!$H$2:$H$10401,A4,'Все позиции'!$L$2:$L$10401,B4,'Все позиции'!$F$2:$F$10401,"<>") -> 0 | G4: =IF(F4>0,"да","нет") -> нет
A5: 09-3242_20С1775-ВЖК-1-АС | B5: компл | C5: =COUNTIFS('Все позиции'!$H$2:$H$10401,A5,'Все позиции'!$L$2:$L$10401,B5) -> 1 | D5: =SUMIFS('Все позиции'!$K$2:$K$10401,'Все позиции'!$H$2:$H$10401,A5,'Все позиции'!$L$2:$L$10401,B5) -> 1 | E5: =SUMIFS('Все позиции'!$P$2:$P$10401,'Все позиции'!$H$2:$H$10401,A5,'Все позиции'!$L$2:$L$10401,B5) -> 93348981 | F5: =COUNTIFS('Все позиции'!$H$2:$H$10401,A5,'Все позиции'!$L$2:$L$10401,B5,'Все позиции'!$F$2:$F$10401,"<>") -> 1 | G5: =IF(F5>0,"да","нет") -> да
A6: 09-3242_20С1775-ВЖК-1-ВК | B6: компл | C6: =COUNTIFS('Все позиции'!$H$2:$H$10401,A6,'Все позиции'!$L$2:$L$10401,B6) -> 1 | D6: =SUMIFS('Все позиции'!$K$2:$K$10401,'Все позиции'!$H$2:$H$10401,A6,'Все позиции'!$L$2:$L$10401,B6) -> 1 | E6: =SUMIFS('Все позиции'!$P$2:$P$10401,'Все позиции'!$H$2:$H$10401,A6,'Все позиции'!$L$2:$L$10401,B6) -> 12886933 | F6: =COUNTIFS('Все позиции'!$H$2:$H$10401,A6,'Все позиции'!$L$2:$L$10401,B6,'Все позиции'!$F$2:$F$10401,"<>") -> 1 | G6: =IF(F6>0,"да","нет") -> да
A7: 09-3242_20С1775-ВЖК-1-КМ | B7: компл | C7: =COUNTIFS('Все позиции'!$H$2:$H$10401,A7,'Все позиции'!$L$2:$L$10401,B7) -> 1 | D7: =SUMIFS('Все позиции'!$K$2:$K$10401,'Все позиции'!$H$2:$H$10401,A7,'Все позиции'!$L$2:$L$10401,B7) -> 1 | E7: =SUMIFS('Все позиции'!$P$2:$P$10401,'Все позиции'!$H$2:$H$10401,A7,'Все позиции'!$L$2:$L$10401,B7) -> 93822244 | F7: =COUNTIFS('Все позиции'!$H$2:$H$10401,A7,'Все позиции'!$L$2:$L$10401,B7,'Все позиции'!$F$2:$F$10401,"<>") -> 1 | G7: =IF(F7>0,"да","нет") -> да
A8: 09-3242_20С1775-ВЖК-1-ОВ | B8: компл | C8: =COUNTIFS('Все позиции'!$H$2:$H$10401,A8,'Все позиции'!$L$2:$L$10401,B8) -> 1 | D8: =SUMIFS('Все позиции'!$K$2:$K$10401,'Все позиции'!$H$2:$H$10401,A8,'Все позиции'!$L$2:$L$10401,B8) -> 1 | E8: =SUMIFS('Все позиции'!$P$2:$P$10401,'Все позиции'!$H$2:$H$10401,A8,'Все позиции'!$L$2:$L$10401,B8) -> 51256057 | F8: =COUNTIFS('Все позиции'!$H$2:$H$10401,A8,'Все позиции'!$L$2:$L$10401,B8,'Все позиции'!$F$2:$F$10401,"<>") -> 1 | G8: =IF(F8>0,"да","нет") -> да
A9: 09-3242_20С1775-ВЖК-1-ОС | B9: компл | C9: =COUNTIFS('Все позиции'!$H$2:$H$10401,A9,'Все позиции'!$L$2:$L$10401,B9) -> 1 | D9: =SUMIFS('Все позиции'!$K$2:$K$10401,'Все позиции'!$H$2:$H$10401,A9,'Все позиции'!$L$2:$L$10401,B9) -> 1 | E9: =SUMIFS('Все позиции'!$P$2:$P$10401,'Все позиции'!$H$2:$H$10401,A9,'Все позиции'!$L$2:$L$10401,B9) -> 1177531 | F9: =COUNTIFS('Все позиции'!$H$2:$H$10401,A9,'Все позиции'!$L$2:$L$10401,B9,'Все позиции'!$F$2:$F$10401,"<>") -> 1 | G9: =IF(F9>0,"да","нет") -> да
A10: 09-3242_20С1775-ВЖК-1-ТХТ | B10: компл | C10: =COUNTIFS('Все позиции'!$H$2:$H$10401,A10,'Все позиции'!$L$2:$L$10401,B10) -> 1 | D10: =SUMIFS('Все позиции'!$K$2:$K$10401,'Все позиции'!$H$2:$H$10401,A10,'Все позиции'!$L$2:$L$10401,B10) -> 1 | E10: =SUMIFS('Все позиции'!$P$2:$P$10401,'Все позиции'!$H$2:$H$10401,A10,'Все позиции'!$L$2:$L$10401,B10) -> 41770516 | F10: =COUNTIFS('Все позиции'!$H$2:$H$10401,A10,'Все позиции'!$L$2:$L$10401,B10,'Все позиции'!$F$2:$F$10401,"<>") -> 1 | G10: =IF(F10>0,"да","нет") -> да
A11: 09-3242_20С1775-ВЖК-1-ЭОМ | B11: компл | C11: =COUNTIFS('Все позиции'!$H$2:$H$10401,A11,'Все позиции'!$L$2:$L$10401,B11) -> 1 | D11: =SUMIFS('Все позиции'!$K$2:$K$10401,'Все позиции'!$H$2:$H$10401,A11,'Все позиции'!$L$2:$L$10401,B11) -> 1 | E11: =SUMIFS('Все позиции'!$P$2:$P$10401,'Все позиции'!$H$2:$H$10401,A11,'Все позиции'!$L$2:$L$10401,B11) -> 7788617.8 | F11: =COUNTIFS('Все позиции'!$H$2:$H$10401,A11,'Все позиции'!$L$2:$L$10401,B11,'Все позиции'!$F$2:$F$10401,"<>") -> 1 | G11: =IF(F11>0,"да","нет") -> да
A12: 09-3242_20С1775-ВЖК-2-АС | B12: компл | C12: =COUNTIFS('Все позиции'!$H$2:$H$10401,A12,'Все позиции'!$L$2:$L$10401,B12) -> 1 | D12: =SUMIFS('Все позиции'!$K$2:$K$10401,'Все позиции'!$H$2:$H$10401,A12,'Все позиции'!$L$2:$L$10401,B12) -> 1 | E12: =SUMIFS('Все позиции'!$P$2:$P$10401,'Все позиции'!$H$2:$H$10401,A12,'Все позиции'!$L$2:$L$10401,B12) -> 1.1772003e+08 | F12: =COUNTIFS('Все позиции'!$H$2:$H$10401,A12,'Все позиции'!$L$2:$L$10401,B12,'Все позиции'!$F$2:$F$10401,"<>") -> 1 | G12: =IF(F12>0,"да","нет") -> да
A13: 09-3242_20С1775-ВЖК-2-ВК | B13: компл | C13: =COUNTIFS('Все позиции'!$H$2:$H$10401,A13,'Все позиции'!$L$2:$L$10401,B13) -> 1 | D13: =SUMIFS('Все позиции'!$K$2:$K$10401,'Все позиции'!$H$2:$H$10401,A13,'Все позиции'!$L$2:$L$10401,B13) -> 1 | E13: =SUMIFS('Все позиции'!$P$2:$P$10401,'Все позиции'!$H$2:$H$10401,A13,'Все позиции'!$L$2:$L$10401,B13) -> 8970383.4 | F13: =COUNTIFS('Все позиции'!$H$2:$H$10401,A13,'Все позиции'!$L$2:$L$10401,B13,'Все позиции'!$F$2:$F$10401,"<>") -> 1 | G13: =IF(F13>0,"да","нет") -> да
... A8133: Ящик ЯТПВ-0,25-2А УХЛЗ ТУ 16-536.024-75 с понижающим разделительным трансформатором 220/24 В, степень защиты IР54 | B8133: шт | C8133: =COUNTIFS('Все позиции'!$H$2:$H$10401,A8133,'Все позиции'!$L$2:$L$10401,B8133) -> 2 | D8133: =SUMIFS('Все позиции'!$K$2:$K$10401,'Все позиции'!$H$2:$H$10401,A8133,'Все позиции'!$L$2:$L$10401,B8133) -> 7 | E8133: =SUMIFS('Все позиции'!$P$2:$P$10401,'Все позиции'!$H$2:$H$10401,A8133,'Все позиции'!$L$2:$L$10401,B8133) -> 69777.9 | F8133: =COUNTIFS('Все позиции'!$H$2:$H$10401,A8133,'Все позиции'!$L$2:$L$10401,B8133,'Все позиции'!$F$2:$F$10401,"<>") -> 1 | G8133: =IF(F8133>0,"да","нет") -> да
