Workbook

Sheet Продажи
B2: ТРАНСТЕХКОМ Продажи и исполнение | C2: ТРАНСТЕХКОМ Продажи и исполнение | D2: ТРАНСТЕХКОМ Продажи и исполнение | E2: ТРАНСТЕХКОМ Продажи и исполнение | F2: ТРАНСТЕХКОМ Продажи и исполнение | G2: ТРАНСТЕХКОМ Продажи и исполнение | H2: ТРАНСТЕХКОМ Продажи и исполнение | I2: ТРАНСТЕХКОМ Продажи и исполнение | J2: ТРАНСТЕХКОМ Продажи и исполнение | K2: ТРАНСТЕХКОМ Продажи и исполнение | L2: ТРАНСТЕХКОМ Продажи и исполнение | M2: ТРАНСТЕХКОМ Продажи и исполнение | N2: ТРАНСТЕХКОМ Продажи и исполнение | O2: ТРАНСТЕХКОМ Продажи и исполнение | P2: ТРАНСТЕХКОМ Продажи и исполнение | Q2: ТРАНСТЕХКОМ Продажи и исполнение
B3: Демонстрационные данные. Обновлённый макет под процессы ТТК, без подключения к учётным системам. | C3: Демонстрационные данные. Обновлённый макет под процессы ТТК, без подключения к учётным системам. | D3: Демонстрационные данные. Обновлённый макет под процессы ТТК, без подключения к учётным системам. | E3: Демонстрационные данные. Обновлённый макет под процессы ТТК, без подключения к учётным системам. | F3: Демонстрационные данные. Обновлённый макет под процессы ТТК, без подключения к учётным системам. | G3: Демонстрационные данные. Обновлённый макет под процессы ТТК, без подключения к учётным системам. | H3: Демонстрационные данные. Обновлённый макет под процессы ТТК, без подключения к учётным системам. | I3: Демонстрационные данные. Обновлённый макет под процессы ТТК, без подключения к учётным системам. | J3: Демонстрационные данные. Обновлённый макет под процессы ТТК, без подключения к учётным системам. | K3: Демонстрационные данные. Обновлённый макет под процессы ТТК, без подключения к учётным системам. | L3: Демонстрационные данные. Обновлённый макет под процессы ТТК, без подключения к учётным системам. | M3: Демонстрационные данные. Обновлённый макет под процессы ТТК, без подключения к учётным системам. | N3: Демонстрационные данные. Обновлённый макет под процессы ТТК, без подключения к учётным системам. | O3: Демонстрационные данные. Обновлённый макет под процессы ТТК, без подключения к учётным системам. | P3: Демонстрационные данные. Обновлённый макет под процессы ТТК, без подключения к учётным системам. | Q3: Демонстрационные данные. Обновлённый макет под процессы ТТК, без подключения к учётным системам.
B4: Срез | C4: Срез | D4: 46321.375 | E4: 46321.375 | F4: 46321.375 | G4: Сотрудник | H4: Сотрудник | I4: Все | J4: Все | K4: Все | L4: Все | M4: Продажи | N4: Продажи | O4: Все | P4: Все | Q4: Все
B7: Действия на сегодня | C7: Действия на сегодня | D7: Действия на сегодня | E7: Действия на сегодня | F7: Жёсткие сроки ≤ 48 ч | G7: Жёсткие сроки ≤ 48 ч | H7: Жёсткие сроки ≤ 48 ч | I7: Жёсткие сроки ≤ 48 ч | J7: Просрочено у продаж | K7: Просрочено у продаж | L7: Просрочено у продаж | M7: Просрочено у продаж | N7: Ожидание других | O7: Ожидание других | P7: Ожидание других | Q7: Ожидание других
B8: =COUNTIFS(Действия!$S$7:$S$106,1,Действия!$F$7:$F$106,">="&INT($D$4),Действия!$F$7:$F$106,"<"&INT($D$4)+1) -> 9 | F8: =COUNTIFS(Действия!$S$7:$S$106,1,Действия!$P$7:$P$106,1) -> 4 | J8: =COUNTIFS(Действия!$S$7:$S$106,1,Действия!$Q$7:$Q$106,1) -> 2 | N8: =COUNTIFS(Действия!$S$7:$S$106,1,Действия!$R$7:$R$106,1) -> 7
B10: ="Объектов: "&SUM(Реестр!$X$7:$X$106)&" • без следующего действия продавца: "&COUNTIFS(Реестр!$X$7:$X$106,1,Реестр!$Z$7:$Z$106,1)&" • без срока этапа: "&COUNTIFS(Реестр!$X$7:$X$106,1,Реестр!$AC$7:$AC$106,1)&" • карточки сверху считают действия, не сделки" -> Объектов: 15 • без следующего действия продавца: 4 • без срока этапа: 0 • карточки сверху считают действия, не сделки
B12: СЕГОДНЯ И КРИТИЧЕСКИЕ СРОКИ | C12: СЕГОДНЯ И КРИТИЧЕСКИЕ СРОКИ | D12: СЕГОДНЯ И КРИТИЧЕСКИЕ СРОКИ | E12: СЕГОДНЯ И КРИТИЧЕСКИЕ СРОКИ | F12: СЕГОДНЯ И КРИТИЧЕСКИЕ СРОКИ | G12: СЕГОДНЯ И КРИТИЧЕСКИЕ СРОКИ | H12: СЕГОДНЯ И КРИТИЧЕСКИЕ СРОКИ | I12: СЕГОДНЯ И КРИТИЧЕСКИЕ СРОКИ | J12: СЕГОДНЯ И КРИТИЧЕСКИЕ СРОКИ | K12: СЕГОДНЯ И КРИТИЧЕСКИЕ СРОКИ | L12: СЕГОДНЯ И КРИТИЧЕСКИЕ СРОКИ | M12: СЕГОДНЯ И КРИТИЧЕСКИЕ СРОКИ | N12: СЕГОДНЯ И КРИТИЧЕСКИЕ СРОКИ | O12: СЕГОДНЯ И КРИТИЧЕСКИЕ СРОКИ | P12: СЕГОДНЯ И КРИТИЧЕСКИЕ СРОКИ | Q12: СЕГОДНЯ И КРИТИЧЕСКИЕ СРОКИ
B13: Объект | C13: Объект | D13: Действие | E13: Действие | F13: Действие | G13: Действие | H13: Действие | I13: Кто выполняет | J13: Кто выполняет | K13: Кто выполняет | L13: Срок | M13: Срок | N13: Срок | O13: Причина приоритета | P13: Причина приоритета | Q13: Причина приоритета
B14: =IF(COUNT(Действия!$U$7:$U$106)<1,"",IF(INDEX(Действия!$B$7:$B$106,MATCH(1,Действия!$U$7:$U$106,0))=0,"Нет данных",INDEX(Действия!$B$7:$B$106,MATCH(1,Действия!$U$7:$U$106,0)))) -> С-107 | D14: =IF(COUNT(Действия!$U$7:$U$106)<1,"",IF(INDEX(Действия!$C$7:$C$106,MATCH(1,Действия!$U$7:$U$106,0))=0,"Нет данных",INDEX(Действия!$C$7:$C$106,MATCH(1,Действия!$U$7:$U$106,0)))) -> Подать ответ на технический дозапрос | I14: =IF(COUNT(Действия!$U$7:$U$106)<1,"",IF(INDEX(Действия!$E$7:$E$106,MATCH(1,Действия!$U$7:$U$106,0))=0,"Нет данных",INDEX(Действия!$E$7:$E$106,MATCH(1,Действия!$U$7:$U$106,0)))) -> Тендерный специалист | L14: =IF(COUNT(Действия!$U$7:$U$106)<1,"",IF(INDEX(Действия!$F$7:$F$106,MATCH(1,Действия!$U$7:$U$106,0))=0,"Нет данных",INDEX(Действия!$F$7:$F$106,MATCH(1,Действия!$U$7:$U$106,0)))) -> 46321.458 | O14: =IF(COUNT(Действия!$U$7:$U$106)<1,"",IF(INDEX(Действия!$P$7:$P$106,MATCH(1,Действия!$U$7:$U$106,0))=1,"Жёсткий срок",IF(INDEX(Действия!$Q$7:$Q$106,MATCH(1,Действия!$U$7:$U$106,0))=1,"Просрочка продаж",IF(INDEX(Действия!$O$7:$O$106,MATCH(1,Действия!$U$7:$U$106,0))>0,"Просрочка ожидания",IF(INDEX(Действия!$I$7:$I$106,MATCH(1,Действия!$U$7:$U$106,0))="Да","Решение ИД","Сегодня"))))) -> Жёсткий срок
B15: =IF(COUNT(Действия!$U$7:$U$106)<2,"",IF(INDEX(Действия!$B$7:$B$106,MATCH(2,Действия!$U$7:$U$106,0))=0,"Нет данных",INDEX(Действия!$B$7:$B$106,MATCH(2,Действия!$U$7:$U$106,0)))) -> И-202 | D15: =IF(COUNT(Действия!$U$7:$U$106)<2,"",IF(INDEX(Действия!$C$7:$C$106,MATCH(2,Действия!$U$7:$U$106,0))=0,"Нет данных",INDEX(Действия!$C$7:$C$106,MATCH(2,Действия!$U$7:$U$106,0)))) -> Согласовать изменённую дату с клиентом | I15: =IF(COUNT(Действия!$U$7:$U$106)<2,"",IF(INDEX(Действия!$E$7:$E$106,MATCH(2,Действия!$U$7:$U$106,0))=0,"Нет данных",INDEX(Действия!$E$7:$E$106,MATCH(2,Действия!$U$7:$U$106,0)))) -> Менеджер 2 | L15: =IF(COUNT(Действия!$U$7:$U$106)<2,"",IF(INDEX(Действия!$F$7:$F$106,MATCH(2,Действия!$U$7:$U$106,0))=0,"Нет данных",INDEX(Действия!$F$7:$F$106,MATCH(2,Действия!$U$7:$U$106,0)))) -> 46321.542 | O15: =IF(COUNT(Действия!$U$7:$U$106)<2,"",IF(INDEX(Действия!$P$7:$P$106,MATCH(2,Действия!$U$7:$U$106,0))=1,"Жёсткий срок",IF(INDEX(Действия!$Q$7:$Q$106,MATCH(2,Действия!$U$7:$U$106,0))=1,"Просрочка продаж",IF(INDEX(Действия!$O$7:$O$106,MATCH(2,Действия!$U$7:$U$106,0))>0,"Просрочка ожидания",IF(INDEX(Действия!$I$7:$I$106,MATCH(2,Действия!$U$7:$U$106,0))="Да","Решение ИД","Сегодня"))))) -> Жёсткий срок
B16: =IF(COUNT(Действия!$U$7:$U$106)<3,"",IF(INDEX(Действия!$B$7:$B$106,MATCH(3,Действия!$U$7:$U$106,0))=0,"Нет данных",INDEX(Действия!$B$7:$B$106,MATCH(3,Действия!$U$7:$U$106,0)))) -> С-109 | D16: =IF(COUNT(Действия!$U$7:$U$106)<3,"",IF(INDEX(Действия!$C$7:$C$106,MATCH(3,Действия!$U$7:$U$106,0))=0,"Нет данных",INDEX(Действия!$C$7:$C$106,MATCH(3,Действия!$U$7:$U$106,0)))) -> Подтвердить обеспечение заявки | I16: =IF(COUNT(Действия!$U$7:$U$106)<3,"",IF(INDEX(Действия!$E$7:$E$106,MATCH(3,Действия!$U$7:$U$106,0))=0,"Нет данных",INDEX(Действия!$E$7:$E$106,MATCH(3,Действия!$U$7:$U$106,0)))) -> Финансовый блок | L16: =IF(COUNT(Действия!$U$7:$U$106)<3,"",IF(INDEX(Действия!$F$7:$F$106,MATCH(3,Действия!$U$7:$U$106,0))=0,"Нет данных",INDEX(Действия!$F$7:$F$106,MATCH(3,Действия!$U$7:$U$106,0)))) -> 46321.667 | O16: =IF(COUNT(Действия!$U$7:$U$106)<3,"",IF(INDEX(Действия!$P$7:$P$106,MATCH(3,Действия!$U$7:$U$106,0))=1,"Жёсткий срок",IF(INDEX(Действия!$Q$7:$Q$106,MATCH(3,Действия!$U$7:$U$106,0))=1,"Просрочка продаж",IF(INDEX(Действия!$O$7:$O$106,MATCH(3,Действия!$U$7:$U$106,0))>0,"Просрочка ожидания",IF(INDEX(Действия!$I$7:$I$106,MATCH(3,Действия!$U$7:$U$106,0))="Да","Решение ИД","Сегодня"))))) -> Жёсткий срок
B17: =IF(COUNT(Действия!$U$7:$U$106)<4,"",IF(INDEX(Действия!$B$7:$B$106,MATCH(4,Действия!$U$7:$U$106,0))=0,"Нет данных",INDEX(Действия!$B$7:$B$106,MATCH(4,Действия!$U$7:$U$106,0)))) -> С-109 | D17: =IF(COUNT(Действия!$U$7:$U$106)<4,"",IF(INDEX(Действия!$C$7:$C$106,MATCH(4,Действия!$U$7:$U$106,0))=0,"Нет данных",INDEX(Действия!$C$7:$C$106,MATCH(4,Действия!$U$7:$U$106,0)))) -> Подать тендерную заявку | I17: =IF(COUNT(Действия!$U$7:$U$106)<4,"",IF(INDEX(Действия!$E$7:$E$106,MATCH(4,Действия!$U$7:$U$106,0))=0,"Нет данных",INDEX(Действия!$E$7:$E$106,MATCH(4,Действия!$U$7:$U$106,0)))) -> Тендерный специалист | L17: =IF(COUNT(Действия!$U$7:$U$106)<4,"",IF(INDEX(Действия!$F$7:$F$106,MATCH(4,Действия!$U$7:$U$106,0))=0,"Нет данных",INDEX(Действия!$F$7:$F$106,MATCH(4,Действия!$U$7:$U$106,0)))) -> 46322.5 | O17: =IF(COUNT(Действия!$U$7:$U$106)<4,"",IF(INDEX(Действия!$P$7:$P$106,MATCH(4,Действия!$U$7:$U$106,0))=1,"Жёсткий срок",IF(INDEX(Действия!$Q$7:$Q$106,MATCH(4,Действия!$U$7:$U$106,0))=1,"Просрочка продаж",IF(INDEX(Действия!$O$7:$O$106,MATCH(4,Действия!$U$7:$U$106,0))>0,"Просрочка ожидания",IF(INDEX(Действия!$I$7:$I$106,MATCH(4,Действия!$U$7:$U$106,0))="Да","Решение ИД","Сегодня"))))) -> Жёсткий срок
B18: =IF(COUNT(Действия!$U$7:$U$106)<5,"",IF(INDEX(Действия!$B$7:$B$106,MATCH(5,Действия!$U$7:$U$106,0))=0,"Нет данных",INDEX(Действия!$B$7:$B$106,MATCH(5,Действия!$U$7:$U$106,0)))) -> С-102 | D18: =IF(COUNT(Действия!$U$7:$U$106)<5,"",IF(INDEX(Действия!$C$7:$C$106,MATCH(5,Действия!$U$7:$U$106,0))=0,"Нет данных",INDEX(Действия!$C$7:$C$106,MATCH(5,Действия!$U$7:$U$106,0)))) -> Получить сопоставимое КП завода | I18: =IF(COUNT(Действия!$U$7:$U$106)<5,"",IF(INDEX(Действия!$E$7:$E$106,MATCH(5,Действия!$U$7:$U$106,0))=0,"Нет данных",INDEX(Действия!$E$7:$E$106,MATCH(5,Действия!$U$7:$U$106,0)))) -> Снабженец | L18: =IF(COUNT(Действия!$U$7:$U$106)<5,"",IF(INDEX(Действия!$F$7:$F$106,MATCH(5,Действия!$U$7:$U$106,0))=0,"Нет данных",INDEX(Действия!$F$7:$F$106,MATCH(5,Действия!$U$7:$U$106,0)))) -> 46319.667 | O18: =IF(COUNT(Действия!$U$7:$U$106)<5,"",IF(INDEX(Действия!$P$7:$P$106,MATCH(5,Действия!$U$7:$U$106,0))=1,"Жёсткий срок",IF(INDEX(Действия!$Q$7:$Q$106,MATCH(5,Действия!$U$7:$U$106,0))=1,"Просрочка продаж",IF(INDEX(Действия!$O$7:$O$106,MATCH(5,Действия!$U$7:$U$106,0))>0,"Просрочка ожидания",IF(INDEX(Действия!$I$7:$I$106,MATCH(5,Действия!$U$7:$U$106,0))="Да","Решение ИД","Сегодня"))))) -> Просрочка ожидания
B19: =IF(COUNT(Действия!$U$7:$U$106)<6,"",IF(INDEX(Действия!$B$7:$B$106,MATCH(6,Действия!$U$7:$U$106,0))=0,"Нет данных",INDEX(Действия!$B$7:$B$106,MATCH(6,Действия!$U$7:$U$106,0)))) -> И-203 | D19: =IF(COUNT(Действия!$U$7:$U$106)<6,"",IF(INDEX(Действия!$C$7:$C$106,MATCH(6,Действия!$U$7:$U$106,0))=0,"Нет данных",INDEX(Действия!$C$7:$C$106,MATCH(6,Действия!$U$7:$U$106,0)))) -> Согласовать дату погашения долга | I19: =IF(COUNT(Действия!$U$7:$U$106)<6,"",IF(INDEX(Действия!$E$7:$E$106,MATCH(6,Действия!$U$7:$U$106,0))=0,"Нет данных",INDEX(Действия!$E$7:$E$106,MATCH(6,Действия!$U$7:$U$106,0)))) -> Тендерный специалист | L19: =IF(COUNT(Действия!$U$7:$U$106)<6,"",IF(INDEX(Действия!$F$7:$F$106,MATCH(6,Действия!$U$7:$U$106,0))=0,"Нет данных",INDEX(Действия!$F$7:$F$106,MATCH(6,Действия!$U$7:$U$106,0)))) -> 46320.583 | O19: =IF(COUNT(Действия!$U$7:$U$106)<6,"",IF(INDEX(Действия!$P$7:$P$106,MATCH(6,Действия!$U$7:$U$106,0))=1,"Жёсткий срок",IF(INDEX(Действия!$Q$7:$Q$106,MATCH(6,Действия!$U$7:$U$106,0))=1,"Просрочка продаж",IF(INDEX(Действия!$O$7:$O$106,MATCH(6,Действия!$U$7:$U$106,0))>0,"Просрочка ожидания",IF(INDEX(Действия!$I$7:$I$106,MATCH(6,Действия!$U$7:$U$106,0))="Да","Решение ИД","Сегодня"))))) -> Просрочка продаж
B20: Сначала жёсткие сроки, затем прочие просрочки и задачи на сегодня. Внутри группы — ближайший срок. | C20: Сначала жёсткие сроки, затем прочие просрочки и задачи на сегодня. Внутри группы — ближайший срок. | D20: Сначала жёсткие сроки, затем прочие просрочки и задачи на сегодня. Внутри группы — ближайший срок. | E20: Сначала жёсткие сроки, затем прочие просрочки и задачи на сегодня. Внутри группы — ближайший срок. | F20: Сначала жёсткие сроки, затем прочие просрочки и задачи на сегодня. Внутри группы — ближайший срок. | G20: Сначала жёсткие сроки, затем прочие просрочки и задачи на сегодня. Внутри группы — ближайший срок. | H20: Сначала жёсткие сроки, затем прочие просрочки и задачи на сегодня. Внутри группы — ближайший срок. | I20: Сначала жёсткие сроки, затем прочие просрочки и задачи на сегодня. Внутри группы — ближайший срок. | J20: Сначала жёсткие сроки, затем прочие просрочки и задачи на сегодня. Внутри группы — ближайший срок. | K20: Сначала жёсткие сроки, затем прочие просрочки и задачи на сегодня. Внутри группы — ближайший срок. | L20: Сначала жёсткие сроки, затем прочие просрочки и задачи на сегодня. Внутри группы — ближайший срок. | M20: Сначала жёсткие сроки, затем прочие просрочки и задачи на сегодня. Внутри группы — ближайший срок. | N20: Сначала жёсткие сроки, затем прочие просрочки и задачи на сегодня. Внутри группы — ближайший срок. | O20: Сначала жёсткие сроки, затем прочие просрочки и задачи на сегодня. Внутри группы — ближайший срок. | P20: Сначала жёсткие сроки, затем прочие просрочки и задачи на сегодня. Внутри группы — ближайший срок. | Q20: Сначала жёсткие сроки, затем прочие просрочки и задачи на сегодня. Внутри группы — ближайший срок.
B22: ГДЕ НАХОДИТСЯ РАБОТА | C22: ГДЕ НАХОДИТСЯ РАБОТА | D22: ГДЕ НАХОДИТСЯ РАБОТА | E22: ГДЕ НАХОДИТСЯ РАБОТА | F22: ГДЕ НАХОДИТСЯ РАБОТА | G22: ГДЕ НАХОДИТСЯ РАБОТА | H22: ГДЕ НАХОДИТСЯ РАБОТА | I22: ГДЕ НАХОДИТСЯ РАБОТА | K22: ЧЕГО НЕ ХВАТАЕТ ДЛЯ РАСЧЁТА | L22: ЧЕГО НЕ ХВАТАЕТ ДЛЯ РАСЧЁТА | M22: ЧЕГО НЕ ХВАТАЕТ ДЛЯ РАСЧЁТА | N22: ЧЕГО НЕ ХВАТАЕТ ДЛЯ РАСЧЁТА | O22: ЧЕГО НЕ ХВАТАЕТ ДЛЯ РАСЧЁТА | P22: ЧЕГО НЕ ХВАТАЕТ ДЛЯ РАСЧЁТА | Q22: ЧЕГО НЕ ХВАТАЕТ ДЛЯ РАСЧЁТА
B23: Группа этапов | C23: Группа этапов | D23: Группа этапов | E23: Группа этапов | F23: Группа этапов | G23: Всего | H23: Просрочено | I23: Просрочено
B24: Лиды | C24: Лиды | D24: Лиды | E24: Лиды | F24: Лиды | G24: =COUNTIFS(Реестр!$X$7:$X$106,1,Реестр!$AB$7:$AB$106,B24) -> 3 | H24: =COUNTIFS(Реестр!$X$7:$X$106,1,Реестр!$AB$7:$AB$106,B24,Реестр!$Y$7:$Y$106,1) -> 1 | K24: ТЗ и объёмы | L24: ТЗ и объёмы | M24: ТЗ и объёмы | N24: ТЗ и объёмы | O24: ТЗ и объёмы | P24: =COUNTIFS(Реестр!$X$7:$X$106,1,Реестр!$AB$7:$AB$106,"Расчёт / решение",Реестр!$I$7:$I$106,"Нет")+COUNTIFS(Реестр!$X$7:$X$106,1,Реестр!$AB$7:$AB$106,"Расчёт / решение",Реестр!$I$7:$I$106,"") -> 0
B25: Запрос / проверка | C25: Запрос / проверка | D25: Запрос / проверка | E25: Запрос / проверка | F25: Запрос / проверка | G25: =COUNTIFS(Реестр!$X$7:$X$106,1,Реестр!$AB$7:$AB$106,B25) -> 1 | H25: =COUNTIFS(Реестр!$X$7:$X$106,1,Реестр!$AB$7:$AB$106,B25,Реестр!$Y$7:$Y$106,1) -> 1 | K25: Предложение завода | L25: Предложение завода | M25: Предложение завода | N25: Предложение завода | O25: Предложение завода | P25: =COUNTIFS(Реестр!$X$7:$X$106,1,Реестр!$AB$7:$AB$106,"Расчёт / решение",Реестр!$J$7:$J$106,"Нет")+COUNTIFS(Реестр!$X$7:$X$106,1,Реестр!$AB$7:$AB$106,"Расчёт / решение",Реестр!$J$7:$J$106,"") -> 1
B26: Расчёт / решение | C26: Расчёт / решение | D26: Расчёт / решение | E26: Расчёт / решение | F26: Расчёт / решение | G26: =COUNTIFS(Реестр!$X$7:$X$106,1,Реестр!$AB$7:$AB$106,B26) -> 2 | H26: =COUNTIFS(Реестр!$X$7:$X$106,1,Реестр!$AB$7:$AB$106,B26,Реестр!$Y$7:$Y$106,1) -> 1 | K26: Расчёт логистики | L26: Расчёт логистики | M26: Расчёт логистики | N26: Расчёт логистики | O26: Расчёт логистики | P26: =COUNTIFS(Реестр!$X$7:$X$106,1,Реестр!$AB$7:$AB$106,"Расчёт / решение",Реестр!$K$7:$K$106,"Нет")+COUNTIFS(Реестр!$X$7:$X$106,1,Реестр!$AB$7:$AB$106,"Расчёт / решение",Реестр!$K$7:$K$106,"") -> 1
B27: КП / подготовка | C27: КП / подготовка | D27: КП / подготовка | E27: КП / подготовка | F27: КП / подготовка | G27: =COUNTIFS(Реестр!$X$7:$X$106,1,Реестр!$AB$7:$AB$106,B27) -> 3 | H27: =COUNTIFS(Реестр!$X$7:$X$106,1,Реестр!$AB$7:$AB$106,B27,Реестр!$Y$7:$Y$106,1) -> 1 | K27: Дополнительные расходы | L27: Дополнительные расходы | M27: Дополнительные расходы | N27: Дополнительные расходы | O27: Дополнительные расходы | P27: =COUNTIFS(Реестр!$X$7:$X$106,1,Реестр!$AB$7:$AB$106,"Расчёт / решение",Реестр!$L$7:$L$106,"Нет")+COUNTIFS(Реестр!$X$7:$X$106,1,Реестр!$AB$7:$AB$106,"Расчёт / решение",Реестр!$L$7:$L$106,"") -> 0
B28: Переговоры / подача | C28: Переговоры / подача | D28: Переговоры / подача | E28: Переговоры / подача | F28: Переговоры / подача | G28: =COUNTIFS(Реестр!$X$7:$X$106,1,Реестр!$AB$7:$AB$106,B28) -> 2 | H28: =COUNTIFS(Реестр!$X$7:$X$106,1,Реестр!$AB$7:$AB$106,B28,Реестр!$Y$7:$Y$106,1) -> 0 | K28: Согласованная цена | L28: Согласованная цена | M28: Согласованная цена | N28: Согласованная цена | O28: Согласованная цена | P28: =COUNTIFS(Реестр!$X$7:$X$106,1,Реестр!$AB$7:$AB$106,"Расчёт / решение",Реестр!$M$7:$M$106,"Нет")+COUNTIFS(Реестр!$X$7:$X$106,1,Реестр!$AB$7:$AB$106,"Расчёт / решение",Реестр!$M$7:$M$106,"") -> 2
B29: Договор / результат | C29: Договор / результат | D29: Договор / результат | E29: Договор / результат | F29: Договор / результат | G29: =COUNTIFS(Реестр!$X$7:$X$106,1,Реестр!$AB$7:$AB$106,B29) -> 1 | H29: =COUNTIFS(Реестр!$X$7:$X$106,1,Реестр!$AB$7:$AB$106,B29,Реестр!$Y$7:$Y$106,1) -> 1
B30: Передача / исполнение | C30: Передача / исполнение | D30: Передача / исполнение | E30: Передача / исполнение | F30: Передача / исполнение | G30: =COUNTIFS(Реестр!$X$7:$X$106,1,Реестр!$AB$7:$AB$106,B30) -> 2 | H30: =COUNTIFS(Реестр!$X$7:$X$106,1,Реестр!$AB$7:$AB$106,B30,Реестр!$Y$7:$Y$106,1) -> 0 | K30: Количество объектов на расчёте с отсутствующей частью. Готовность — по данным реестра. | L30: Количество объектов на расчёте с отсутствующей частью. Готовность — по данным реестра. | M30: Количество объектов на расчёте с отсутствующей частью. Готовность — по данным реестра. | N30: Количество объектов на расчёте с отсутствующей частью. Готовность — по данным реестра. | O30: Количество объектов на расчёте с отсутствующей частью. Готовность — по данным реестра. | P30: Количество объектов на расчёте с отсутствующей частью. Готовность — по данным реестра. | Q30: Количество объектов на расчёте с отсутствующей частью. Готовность — по данным реестра.
B31: Приёмка / оплата | C31: Приёмка / оплата | D31: Приёмка / оплата | E31: Приёмка / оплата | F31: Приёмка / оплата | G31: =COUNTIFS(Реестр!$X$7:$X$106,1,Реестр!$AB$7:$AB$106,B31) -> 1 | H31: =COUNTIFS(Реестр!$X$7:$X$106,1,Реестр!$AB$7:$AB$106,B31,Реестр!$Y$7:$Y$106,1) -> 0 | K31: Количество объектов на расчёте с отсутствующей частью. Готовность — по данным реестра. | L31: Количество объектов на расчёте с отсутствующей частью. Готовность — по данным реестра. | M31: Количество объектов на расчёте с отсутствующей частью. Готовность — по данным реестра. | N31: Количество объектов на расчёте с отсутствующей частью. Готовность — по данным реестра. | O31: Количество объектов на расчёте с отсутствующей частью. Готовность — по данным реестра. | P31: Количество объектов на расчёте с отсутствующей частью. Готовность — по данным реестра. | Q31: Количество объектов на расчёте с отсутствующей частью. Готовность — по данным реестра.
B33: ОЧЕРЕДЬ СОТРУДНИКОВ | C33: ОЧЕРЕДЬ СОТРУДНИКОВ | D33: ОЧЕРЕДЬ СОТРУДНИКОВ | E33: ОЧЕРЕДЬ СОТРУДНИКОВ | F33: ОЧЕРЕДЬ СОТРУДНИКОВ | G33: ОЧЕРЕДЬ СОТРУДНИКОВ | H33: ОЧЕРЕДЬ СОТРУДНИКОВ | I33: ОЧЕРЕДЬ СОТРУДНИКОВ | J33: ОЧЕРЕДЬ СОТРУДНИКОВ | K33: ОЧЕРЕДЬ СОТРУДНИКОВ | L33: ОЧЕРЕДЬ СОТРУДНИКОВ | M33: ОЧЕРЕДЬ СОТРУДНИКОВ | N33: ОЧЕРЕДЬ СОТРУДНИКОВ | O33: ОЧЕРЕДЬ СОТРУДНИКОВ | P33: ОЧЕРЕДЬ СОТРУДНИКОВ | Q33: ОЧЕРЕДЬ СОТРУДНИКОВ
B34: Сотрудник | C34: Сотрудник | D34: Сотрудник | E34: Сотрудник | F34: Сотрудник | G34: Лиды | H34: Лиды | I34: Сделки | J34: Сделки | K34: Исполнение | L34: Исполнение | M34: Просрочки продаж | N34: Просрочки продаж | O34: Ожидания других | P34: Ожидания других | Q34: Ожидания других
B35: =Реестр!A138 -> Менеджер 1 | G35: =COUNTIFS(Реестр!$X$7:$X$106,1,Реестр!$D$7:$D$106,B35,Реестр!$B$7:$B$106,"Лид") -> 2 | I35: =COUNTIFS(Реестр!$X$7:$X$106,1,Реестр!$D$7:$D$106,B35,Реестр!$B$7:$B$106,"Сделка") -> 3 | K35: =COUNTIFS(Реестр!$X$7:$X$106,1,Реестр!$D$7:$D$106,B35,Реестр!$B$7:$B$106,"Исполнение") -> 1 | M35: =COUNTIFS(Действия!$S$7:$S$106,1,Действия!$L$7:$L$106,B35,Действия!$Q$7:$Q$106,1) -> 0 | O35: =COUNTIFS(Действия!$S$7:$S$106,1,Действия!$L$7:$L$106,B35,Действия!$R$7:$R$106,1) -> 2
B36: =Реестр!A139 -> Менеджер 2 | G36: =COUNTIFS(Реестр!$X$7:$X$106,1,Реестр!$D$7:$D$106,B36,Реестр!$B$7:$B$106,"Лид") -> 1 | I36: =COUNTIFS(Реестр!$X$7:$X$106,1,Реестр!$D$7:$D$106,B36,Реестр!$B$7:$B$106,"Сделка") -> 3 | K36: =COUNTIFS(Реестр!$X$7:$X$106,1,Реестр!$D$7:$D$106,B36,Реестр!$B$7:$B$106,"Исполнение") -> 1 | M36: =COUNTIFS(Действия!$S$7:$S$106,1,Действия!$L$7:$L$106,B36,Действия!$Q$7:$Q$106,1) -> 1 | O36: =COUNTIFS(Действия!$S$7:$S$106,1,Действия!$L$7:$L$106,B36,Действия!$R$7:$R$106,1) -> 2
B37: =Реестр!A140 -> Тендерный специалист | G37: =COUNTIFS(Реестр!$X$7:$X$106,1,Реестр!$D$7:$D$106,B37,Реестр!$B$7:$B$106,"Лид") -> 0 | I37: =COUNTIFS(Реестр!$X$7:$X$106,1,Реестр!$D$7:$D$106,B37,Реестр!$B$7:$B$106,"Сделка") -> 3 | K37: =COUNTIFS(Реестр!$X$7:$X$106,1,Реестр!$D$7:$D$106,B37,Реестр!$B$7:$B$106,"Исполнение") -> 1 | M37: =COUNTIFS(Действия!$S$7:$S$106,1,Действия!$L$7:$L$106,B37,Действия!$Q$7:$Q$106,1) -> 1 | O37: =COUNTIFS(Действия!$S$7:$S$106,1,Действия!$L$7:$L$106,B37,Действия!$R$7:$R$106,1) -> 3
B39: ТРЕБУЕТ РЕШЕНИЯ ИД | C39: ТРЕБУЕТ РЕШЕНИЯ ИД | D39: ТРЕБУЕТ РЕШЕНИЯ ИД | E39: ТРЕБУЕТ РЕШЕНИЯ ИД | F39: ТРЕБУЕТ РЕШЕНИЯ ИД | G39: ТРЕБУЕТ РЕШЕНИЯ ИД | H39: ТРЕБУЕТ РЕШЕНИЯ ИД | I39: ТРЕБУЕТ РЕШЕНИЯ ИД | J39: ТРЕБУЕТ РЕШЕНИЯ ИД | K39: ТРЕБУЕТ РЕШЕНИЯ ИД | L39: ТРЕБУЕТ РЕШЕНИЯ ИД | M39: ТРЕБУЕТ РЕШЕНИЯ ИД | N39: ТРЕБУЕТ РЕШЕНИЯ ИД | O39: ТРЕБУЕТ РЕШЕНИЯ ИД | P39: ТРЕБУЕТ РЕШЕНИЯ ИД | Q39: ТРЕБУЕТ РЕШЕНИЯ ИД
B40: ="Открытых вопросов: "&COUNTIFS(Действия!$S$7:$S$106,1,Действия!$I$7:$I$106,"Да")&". Все вопросы — фильтр «Нужно решение ИД = Да» на листе «Действия»." -> Открытых вопросов: 4. Все вопросы — фильтр «Нужно решение ИД = Да» на листе «Действия».
B41: =IF(COUNT(Действия!$X$7:$X$106)<1,"",INDEX(Действия!$B$7:$B$106,MATCH(1,Действия!$X$7:$X$106,0))) -> С-102 | D41: =IF(COUNT(Действия!$X$7:$X$106)<1,"",IF(INDEX(Действия!$J$7:$J$106,MATCH(1,Действия!$X$7:$X$106,0))=0,"Сформулировать вопрос для ИД",INDEX(Действия!$J$7:$J$106,MATCH(1,Действия!$X$7:$X$106,0)))) -> Определить замену поставщика или согласовать перенос расчёта | N41: =IF(COUNT(Действия!$X$7:$X$106)<1,"",INDEX(Действия!$F$7:$F$106,MATCH(1,Действия!$X$7:$X$106,0))) -> 46319.667
B42: =IF(COUNT(Действия!$X$7:$X$106)<2,"",INDEX(Действия!$B$7:$B$106,MATCH(2,Действия!$X$7:$X$106,0))) -> С-108 | D42: =IF(COUNT(Действия!$X$7:$X$106)<2,"",IF(INDEX(Действия!$J$7:$J$106,MATCH(2,Действия!$X$7:$X$106,0))=0,"Сформулировать вопрос для ИД",INDEX(Действия!$J$7:$J$106,MATCH(2,Действия!$X$7:$X$106,0)))) -> Решить вопрос по ответственности и срокам договора | N42: =IF(COUNT(Действия!$X$7:$X$106)<2,"",INDEX(Действия!$F$7:$F$106,MATCH(2,Действия!$X$7:$X$106,0))) -> 46320.625
B43: =IF(COUNT(Действия!$X$7:$X$106)<3,"",INDEX(Действия!$B$7:$B$106,MATCH(3,Действия!$X$7:$X$106,0))) -> И-202 | D43: =IF(COUNT(Действия!$X$7:$X$106)<3,"",IF(INDEX(Действия!$J$7:$J$106,MATCH(3,Действия!$X$7:$X$106,0))=0,"Сформулировать вопрос для ИД",INDEX(Действия!$J$7:$J$106,MATCH(3,Действия!$X$7:$X$106,0)))) -> Определить допустимое решение по переносу поставки | N43: =IF(COUNT(Действия!$X$7:$X$106)<3,"",INDEX(Действия!$F$7:$F$106,MATCH(3,Действия!$X$7:$X$106,0))) -> 46321.542
B44: =IF(COUNT(Действия!$X$7:$X$106)<4,"",INDEX(Действия!$B$7:$B$106,MATCH(4,Действия!$X$7:$X$106,0))) -> С-103 | D44: =IF(COUNT(Действия!$X$7:$X$106)<4,"",IF(INDEX(Действия!$J$7:$J$106,MATCH(4,Действия!$X$7:$X$106,0))=0,"Сформулировать вопрос для ИД",INDEX(Действия!$J$7:$J$106,MATCH(4,Действия!$X$7:$X$106,0)))) -> Утвердить цену с учётом доставки и обеспечения | N44: =IF(COUNT(Действия!$X$7:$X$106)<4,"",INDEX(Действия!$F$7:$F$106,MATCH(4,Действия!$X$7:$X$106,0))) -> 46321.583
B46: Жёлтые ячейки — ввод. Реестр: объекты, готовность и данные 1С. Действия: задачи, ожидания и решения. Имена — Реестр!A138:A140. | C46: Жёлтые ячейки — ввод. Реестр: объекты, готовность и данные 1С. Действия: задачи, ожидания и решения. Имена — Реестр!A138:A140. | D46: Жёлтые ячейки — ввод. Реестр: объекты, готовность и данные 1С. Действия: задачи, ожидания и решения. Имена — Реестр!A138:A140. | E46: Жёлтые ячейки — ввод. Реестр: объекты, готовность и данные 1С. Действия: задачи, ожидания и решения. Имена — Реестр!A138:A140. | F46: Жёлтые ячейки — ввод. Реестр: объекты, готовность и данные 1С. Действия: задачи, ожидания и решения. Имена — Реестр!A138:A140. | G46: Жёлтые ячейки — ввод. Реестр: объекты, готовность и данные 1С. Действия: задачи, ожидания и решения. Имена — Реестр!A138:A140. | H46: Жёлтые ячейки — ввод. Реестр: объекты, готовность и данные 1С. Действия: задачи, ожидания и решения. Имена — Реестр!A138:A140. | I46: Жёлтые ячейки — ввод. Реестр: объекты, готовность и данные 1С. Действия: задачи, ожидания и решения. Имена — Реестр!A138:A140. | J46: Жёлтые ячейки — ввод. Реестр: объекты, готовность и данные 1С. Действия: задачи, ожидания и решения. Имена — Реестр!A138:A140. | K46: Жёлтые ячейки — ввод. Реестр: объекты, готовность и данные 1С. Действия: задачи, ожидания и решения. Имена — Реестр!A138:A140. | L46: Жёлтые ячейки — ввод. Реестр: объекты, готовность и данные 1С. Действия: задачи, ожидания и решения. Имена — Реестр!A138:A140. | M46: Жёлтые ячейки — ввод. Реестр: объекты, готовность и данные 1С. Действия: задачи, ожидания и решения. Имена — Реестр!A138:A140. | N46: Жёлтые ячейки — ввод. Реестр: объекты, готовность и данные 1С. Действия: задачи, ожидания и решения. Имена — Реестр!A138:A140. | O46: Жёлтые ячейки — ввод. Реестр: объекты, готовность и данные 1С. Действия: задачи, ожидания и решения. Имена — Реестр!A138:A140. | P46: Жёлтые ячейки — ввод. Реестр: объекты, готовность и данные 1С. Действия: задачи, ожидания и решения. Имена — Реестр!A138:A140. | Q46: Жёлтые ячейки — ввод. Реестр: объекты, готовность и данные 1С. Действия: задачи, ожидания и решения. Имена — Реестр!A138:A140.
B47: Ожидания других отделов не снимают ответственность продавца за контакт с клиентом. Сроки этапов и жёсткие сроки — разные поля. | C47: Ожидания других отделов не снимают ответственность продавца за контакт с клиентом. Сроки этапов и жёсткие сроки — разные поля. | D47: Ожидания других отделов не снимают ответственность продавца за контакт с клиентом. Сроки этапов и жёсткие сроки — разные поля. | E47: Ожидания других отделов не снимают ответственность продавца за контакт с клиентом. Сроки этапов и жёсткие сроки — разные поля. | F47: Ожидания других отделов не снимают ответственность продавца за контакт с клиентом. Сроки этапов и жёсткие сроки — разные поля. | G47: Ожидания других отделов не снимают ответственность продавца за контакт с клиентом. Сроки этапов и жёсткие сроки — разные поля. | H47: Ожидания других отделов не снимают ответственность продавца за контакт с клиентом. Сроки этапов и жёсткие сроки — разные поля. | I47: Ожидания других отделов не снимают ответственность продавца за контакт с клиентом. Сроки этапов и жёсткие сроки — разные поля. | J47: Ожидания других отделов не снимают ответственность продавца за контакт с клиентом. Сроки этапов и жёсткие сроки — разные поля. | K47: Ожидания других отделов не снимают ответственность продавца за контакт с клиентом. Сроки этапов и жёсткие сроки — разные поля. | L47: Ожидания других отделов не снимают ответственность продавца за контакт с клиентом. Сроки этапов и жёсткие сроки — разные поля. | M47: Ожидания других отделов не снимают ответственность продавца за контакт с клиентом. Сроки этапов и жёсткие сроки — разные поля. | N47: Ожидания других отделов не снимают ответственность продавца за контакт с клиентом. Сроки этапов и жёсткие сроки — разные поля. | O47: Ожидания других отделов не снимают ответственность продавца за контакт с клиентом. Сроки этапов и жёсткие сроки — разные поля. | P47: Ожидания других отделов не снимают ответственность продавца за контакт с клиентом. Сроки этапов и жёсткие сроки — разные поля. | Q47: Ожидания других отделов не снимают ответственность продавца за контакт с клиентом. Сроки этапов и жёсткие сроки — разные поля.
B48: ="Контроль данных: действий без связи с объектом — "&COUNTIF(Действия!$L$7:$L$106,"Нет связи")&"; выбранных действий без срока — "&COUNTIFS(Действия!$S$7:$S$106,1,Действия!$O$7:$O$106,"Нет срока") -> Контроль данных: действий без связи с объектом — 0; выбранных действий без срока — 0

Sheet Реестр
A2: Реестр продаж ТТК | B2: Реестр продаж ТТК | C2: Реестр продаж ТТК | D2: Реестр продаж ТТК | E2: Реестр продаж ТТК | F2: Реестр продаж ТТК | G2: Реестр продаж ТТК | H2: Реестр продаж ТТК | I2: Реестр продаж ТТК | J2: Реестр продаж ТТК | K2: Реестр продаж ТТК | L2: Реестр продаж ТТК | M2: Реестр продаж ТТК | N2: Реестр продаж ТТК | O2: Реестр продаж ТТК | P2: Реестр продаж ТТК | Q2: Реестр продаж ТТК | R2: Реестр продаж ТТК | S2: Реестр продаж ТТК | T2: Реестр продаж ТТК | U2: Реестр продаж ТТК
A3: Жёлтые ячейки — ввод. Сохранены 12 исходных примеров, добавлены 3 примера исполнения. Все данные условные. | B3: Жёлтые ячейки — ввод. Сохранены 12 исходных примеров, добавлены 3 примера исполнения. Все данные условные. | C3: Жёлтые ячейки — ввод. Сохранены 12 исходных примеров, добавлены 3 примера исполнения. Все данные условные. | D3: Жёлтые ячейки — ввод. Сохранены 12 исходных примеров, добавлены 3 примера исполнения. Все данные условные. | E3: Жёлтые ячейки — ввод. Сохранены 12 исходных примеров, добавлены 3 примера исполнения. Все данные условные. | F3: Жёлтые ячейки — ввод. Сохранены 12 исходных примеров, добавлены 3 примера исполнения. Все данные условные. | G3: Жёлтые ячейки — ввод. Сохранены 12 исходных примеров, добавлены 3 примера исполнения. Все данные условные. | H3: Жёлтые ячейки — ввод. Сохранены 12 исходных примеров, добавлены 3 примера исполнения. Все данные условные. | I3: Жёлтые ячейки — ввод. Сохранены 12 исходных примеров, добавлены 3 примера исполнения. Все данные условные. | J3: Жёлтые ячейки — ввод. Сохранены 12 исходных примеров, добавлены 3 примера исполнения. Все данные условные. | K3: Жёлтые ячейки — ввод. Сохранены 12 исходных примеров, добавлены 3 примера исполнения. Все данные условные. | L3: Жёлтые ячейки — ввод. Сохранены 12 исходных примеров, добавлены 3 примера исполнения. Все данные условные. | M3: Жёлтые ячейки — ввод. Сохранены 12 исходных примеров, добавлены 3 примера исполнения. Все данные условные. | N3: Жёлтые ячейки — ввод. Сохранены 12 исходных примеров, добавлены 3 примера исполнения. Все данные условные. | O3: Жёлтые ячейки — ввод. Сохранены 12 исходных примеров, добавлены 3 примера исполнения. Все данные условные. | P3: Жёлтые ячейки — ввод. Сохранены 12 исходных примеров, добавлены 3 примера исполнения. Все данные условные. | Q3: Жёлтые ячейки — ввод. Сохранены 12 исходных примеров, добавлены 3 примера исполнения. Все данные условные. | R3: Жёлтые ячейки — ввод. Сохранены 12 исходных примеров, добавлены 3 примера исполнения. Все данные условные. | S3: Жёлтые ячейки — ввод. Сохранены 12 исходных примеров, добавлены 3 примера исполнения. Все данные условные. | T3: Жёлтые ячейки — ввод. Сохранены 12 исходных примеров, добавлены 3 примера исполнения. Все данные условные. | U3: Жёлтые ячейки — ввод. Сохранены 12 исходных примеров, добавлены 3 примера исполнения. Все данные условные.
A4: До 100 объектов. ID уникален. Прямые продажи и тендеры ведутся по своим этапам. На один объект может быть несколько действий. | B4: До 100 объектов. ID уникален. Прямые продажи и тендеры ведутся по своим этапам. На один объект может быть несколько действий. | C4: До 100 объектов. ID уникален. Прямые продажи и тендеры ведутся по своим этапам. На один объект может быть несколько действий. | D4: До 100 объектов. ID уникален. Прямые продажи и тендеры ведутся по своим этапам. На один объект может быть несколько действий. | E4: До 100 объектов. ID уникален. Прямые продажи и тендеры ведутся по своим этапам. На один объект может быть несколько действий. | F4: До 100 объектов. ID уникален. Прямые продажи и тендеры ведутся по своим этапам. На один объект может быть несколько действий. | G4: До 100 объектов. ID уникален. Прямые продажи и тендеры ведутся по своим этапам. На один объект может быть несколько действий. | H4: До 100 объектов. ID уникален. Прямые продажи и тендеры ведутся по своим этапам. На один объект может быть несколько действий. | I4: До 100 объектов. ID уникален. Прямые продажи и тендеры ведутся по своим этапам. На один объект может быть несколько действий. | J4: До 100 объектов. ID уникален. Прямые продажи и тендеры ведутся по своим этапам. На один объект может быть несколько действий. | K4: До 100 объектов. ID уникален. Прямые продажи и тендеры ведутся по своим этапам. На один объект может быть несколько действий. | L4: До 100 объектов. ID уникален. Прямые продажи и тендеры ведутся по своим этапам. На один объект может быть несколько действий. | M4: До 100 объектов. ID уникален. Прямые продажи и тендеры ведутся по своим этапам. На один объект может быть несколько действий. | N4: До 100 объектов. ID уникален. Прямые продажи и тендеры ведутся по своим этапам. На один объект может быть несколько действий. | O4: До 100 объектов. ID уникален. Прямые продажи и тендеры ведутся по своим этапам. На один объект может быть несколько действий. | P4: До 100 объектов. ID уникален. Прямые продажи и тендеры ведутся по своим этапам. На один объект может быть несколько действий. | Q4: До 100 объектов. ID уникален. Прямые продажи и тендеры ведутся по своим этапам. На один объект может быть несколько действий. | R4: До 100 объектов. ID уникален. Прямые продажи и тендеры ведутся по своим этапам. На один объект может быть несколько действий. | S4: До 100 объектов. ID уникален. Прямые продажи и тендеры ведутся по своим этапам. На один объект может быть несколько действий. | T4: До 100 объектов. ID уникален. Прямые продажи и тендеры ведутся по своим этапам. На один объект может быть несколько действий. | U4: До 100 объектов. ID уникален. Прямые продажи и тендеры ведутся по своим этапам. На один объект может быть несколько действий.
A6: ID | B6: Тип | C6: Клиент / объект | D6: Сотрудник | E6: Канал | F6: Этап | G6: Вход на этап | H6: Срок результата этапа | I6: Требования / ТЗ | J6: Предложение завода | K6: Расчёт логистики | L6: Дополнительные расходы | M6: Цена согласована | N6: Результат готов | O6: Подтверждение результата | P6: Передача принята | Q6: Документы приняты | R6: Связанный заказ 1С | S6: Долг, ₽ с НДС | T6: Срок оплаты | U6: Ссылка Битрикс | V6: Ожидаемый результат | W6: Что ещё нужно | X6: Выбран фильтром | Y6: Просрочен этап | Z6: Без открытого действия | AA6: Просроченный долг, ₽ | AB6: Группа этапов | AC6: Без срока этапа | AD6: Сумма предложения, ₽ без НДС
A7: Л-001 | B7: Лид | C7: Компания А | D7: Менеджер 1 | E7: Прямые | F7: Лиды | G7: 46318 | H7: 46321.75 | I7: Не требуется | J7: Не требуется | K7: Не требуется | L7: Не требуется | M7: Не требуется | N7: Нет | P7: Не требуется | Q7: Не требуется | V7: =IF(A7="","",IFERROR(VLOOKUP(F7,$A$111:$C$127,2,FALSE),"Не задан этап")) -> Контакт и подтверждённая потребность | W7: =IF(A7="","",IF(V7="Закрыто","",IF(OR(F7="Расчёт",F7="Решение об участии"),IF(COUNTIF(I7:M7,"Готово")+COUNTIF(I7:M7,"Не требуется")<5,IF(OR(I7="",I7="Нет"),"ТЗ; ","")&IF(OR(J7="",J7="Нет"),"КП завода; ","")&IF(OR(K7="",K7="Нет"),"логистика; ","")&IF(OR(L7="",L7="Нет"),"допрасходы; ","")&IF(OR(M7="",M7="Нет"),"цена продажи; ",""),IF(COUNTIF(I7:M7,"Не требуется")=5,"Проверить применимость расчёта",IF(AND(N7="Готово",O7<>""),"","Подтверждение калькуляции"))),IF(F7="Передача в исполнение",IF(AND(P7="Принято",O7<>""),"","Приём заказа смежниками"),IF(F7="Приёмка и оплата",IF(Q7<>"Принято","Подтверждение приёмки; ","")&IF(S7="","Остаток долга не загружен",IF(S7>0,"Оплата клиента","")),IF(AND(N7="Готово",O7<>""),"",V7)))))) -> Контакт и подтверждённая потребность | X7: =IF(AND(A7<>"",V7<>"Закрыто",OR(Продажи!$I$4="Все",D7=Продажи!$I$4),OR(Продажи!$O$4="Все",E7=Продажи!$O$4)),1,0) -> 1 | Y7: =IF(A7="","",IF(AND(ISNUMBER(H7),H7<Продажи!$D$4,W7<>"",V7<>"Закрыто"),1,0)) -> 0 | Z7: =IF(A7="","",IF(V7="Закрыто",0,IF(COUNTIFS(Действия!$B$7:$B$106,A7,Действия!$N$7:$N$106,1,Действия!$D$7:$D$106,"Продажи")=0,1,0))) -> 0 | AA7: =IF(A7="","",IF(OR(S7="",T7=""),"Нет данных",IF(AND(S7>0,T7<INT(Продажи!$D$4)),S7,0))) -> Нет данных | AB7: =IF(A7="","",IFERROR(VLOOKUP(F7,$A$111:$C$127,3,FALSE),"Не классифицировано")) -> Лиды | AC7: =IF(AND(A7<>"",V7<>"Закрыто",H7=""),1,0) -> 0
A8: Л-002 | B8: Лид | C8: Компания Б | D8: Менеджер 2 | E8: Прямые | F8: Лиды | G8: 46315 | H8: 46319.75 | I8: Не требуется | J8: Не требуется | K8: Не требуется | L8: Не требуется | M8: Не требуется | N8: Нет | P8: Не требуется | Q8: Не требуется | V8: =IF(A8="","",IFERROR(VLOOKUP(F8,$A$111:$C$127,2,FALSE),"Не задан этап")) -> Контакт и подтверждённая потребность | W8: =IF(A8="","",IF(V8="Закрыто","",IF(OR(F8="Расчёт",F8="Решение об участии"),IF(COUNTIF(I8:M8,"Готово")+COUNTIF(I8:M8,"Не требуется")<5,IF(OR(I8="",I8="Нет"),"ТЗ; ","")&IF(OR(J8="",J8="Нет"),"КП завода; ","")&IF(OR(K8="",K8="Нет"),"логистика; ","")&IF(OR(L8="",L8="Нет"),"допрасходы; ","")&IF(OR(M8="",M8="Нет"),"цена продажи; ",""),IF(COUNTIF(I8:M8,"Не требуется")=5,"Проверить применимость расчёта",IF(AND(N8="Готово",O8<>""),"","Подтверждение калькуляции"))),IF(F8="Передача в исполнение",IF(AND(P8="Принято",O8<>""),"","Приём заказа смежниками"),IF(F8="Приёмка и оплата",IF(Q8<>"Принято","Подтверждение приёмки; ","")&IF(S8="","Остаток долга не загружен",IF(S8>0,"Оплата клиента","")),IF(AND(N8="Готово",O8<>""),"",V8)))))) -> Контакт и подтверждённая потребность | X8: =IF(AND(A8<>"",V8<>"Закрыто",OR(Продажи!$I$4="Все",D8=Продажи!$I$4),OR(Продажи!$O$4="Все",E8=Продажи!$O$4)),1,0) -> 1 | Y8: =IF(A8="","",IF(AND(ISNUMBER(H8),H8<Продажи!$D$4,W8<>"",V8<>"Закрыто"),1,0)) -> 1 | Z8: =IF(A8="","",IF(V8="Закрыто",0,IF(COUNTIFS(Действия!$B$7:$B$106,A8,Действия!$N$7:$N$106,1,Действия!$D$7:$D$106,"Продажи")=0,1,0))) -> 0 | AA8: =IF(A8="","",IF(OR(S8="",T8=""),"Нет данных",IF(AND(S8>0,T8<INT(Продажи!$D$4)),S8,0))) -> Нет данных | AB8: =IF(A8="","",IFERROR(VLOOKUP(F8,$A$111:$C$127,3,FALSE),"Не классифицировано")) -> Лиды | AC8: =IF(AND(A8<>"",V8<>"Закрыто",H8=""),1,0) -> 0
A9: Л-003 | B9: Лид | C9: Компания В | D9: Менеджер 1 | E9: Прямые | F9: Лиды | G9: 46319 | H9: 46323.75 | I9: Не требуется | J9: Не требуется | K9: Не требуется | L9: Не требуется | M9: Не требуется | N9: Готово | O9: Демо: карточка потребности | P9: Не требуется | Q9: Не требуется | V9: =IF(A9="","",IFERROR(VLOOKUP(F9,$A$111:$C$127,2,FALSE),"Не задан этап")) -> Контакт и подтверждённая потребность | W9: =IF(A9="","",IF(V9="Закрыто","",IF(OR(F9="Расчёт",F9="Решение об участии"),IF(COUNTIF(I9:M9,"Готово")+COUNTIF(I9:M9,"Не требуется")<5,IF(OR(I9="",I9="Нет"),"ТЗ; ","")&IF(OR(J9="",J9="Нет"),"КП завода; ","")&IF(OR(K9="",K9="Нет"),"логистика; ","")&IF(OR(L9="",L9="Нет"),"допрасходы; ","")&IF(OR(M9="",M9="Нет"),"цена продажи; ",""),IF(COUNTIF(I9:M9,"Не требуется")=5,"Проверить применимость расчёта",IF(AND(N9="Готово",O9<>""),"","Подтверждение калькуляции"))),IF(F9="Передача в исполнение",IF(AND(P9="Принято",O9<>""),"","Приём заказа смежниками"),IF(F9="Приёмка и оплата",IF(Q9<>"Принято","Подтверждение приёмки; ","")&IF(S9="","Остаток долга не загружен",IF(S9>0,"Оплата клиента","")),IF(AND(N9="Готово",O9<>""),"",V9)))))) | X9: =IF(AND(A9<>"",V9<>"Закрыто",OR(Продажи!$I$4="Все",D9=Продажи!$I$4),OR(Продажи!$O$4="Все",E9=Продажи!$O$4)),1,0) -> 1 | Y9: =IF(A9="","",IF(AND(ISNUMBER(H9),H9<Продажи!$D$4,W9<>"",V9<>"Закрыто"),1,0)) -> 0 | Z9: =IF(A9="","",IF(V9="Закрыто",0,IF(COUNTIFS(Действия!$B$7:$B$106,A9,Действия!$N$7:$N$106,1,Действия!$D$7:$D$106,"Продажи")=0,1,0))) -> 0 | AA9: =IF(A9="","",IF(OR(S9="",T9=""),"Нет данных",IF(AND(S9>0,T9<INT(Продажи!$D$4)),S9,0))) -> Нет данных | AB9: =IF(A9="","",IFERROR(VLOOKUP(F9,$A$111:$C$127,3,FALSE),"Не классифицировано")) -> Лиды | AC9: =IF(AND(A9<>"",V9<>"Закрыто",H9=""),1,0) -> 0
A10: С-101 | B10: Сделка | C10: Компания Г | D10: Менеджер 1 | E10: Прямые | F10: Запрос | G10: 46317 | H10: 46320.75 | I10: Не требуется | J10: Не требуется | K10: Не требуется | L10: Не требуется | M10: Не требуется | N10: Нет | P10: Не требуется | Q10: Не требуется | V10: =IF(A10="","",IFERROR(VLOOKUP(F10,$A$111:$C$127,2,FALSE),"Не задан этап")) -> Ведомость требований клиента | W10: =IF(A10="","",IF(V10="Закрыто","",IF(OR(F10="Расчёт",F10="Решение об участии"),IF(COUNTIF(I10:M10,"Готово")+COUNTIF(I10:M10,"Не требуется")<5,IF(OR(I10="",I10="Нет"),"ТЗ; ","")&IF(OR(J10="",J10="Нет"),"КП завода; ","")&IF(OR(K10="",K10="Нет"),"логистика; ","")&IF(OR(L10="",L10="Нет"),"допрасходы; ","")&IF(OR(M10="",M10="Нет"),"цена продажи; ",""),IF(COUNTIF(I10:M10,"Не требуется")=5,"Проверить применимость расчёта",IF(AND(N10="Готово",O10<>""),"","Подтверждение калькуляции"))),IF(F10="Передача в исполнение",IF(AND(P10="Принято",O10<>""),"","Приём заказа смежниками"),IF(F10="Приёмка и оплата",IF(Q10<>"Принято","Подтверждение приёмки; ","")&IF(S10="","Остаток долга не загружен",IF(S10>0,"Оплата клиента","")),IF(AND(N10="Готово",O10<>""),"",V10)))))) -> Ведомость требований клиента | X10: =IF(AND(A10<>"",V10<>"Закрыто",OR(Продажи!$I$4="Все",D10=Продажи!$I$4),OR(Продажи!$O$4="Все",E10=Продажи!$O$4)),1,0) -> 1 | Y10: =IF(A10="","",IF(AND(ISNUMBER(H10),H10<Продажи!$D$4,W10<>"",V10<>"Закрыто"),1,0)) -> 1 | Z10: =IF(A10="","",IF(V10="Закрыто",0,IF(COUNTIFS(Действия!$B$7:$B$106,A10,Действия!$N$7:$N$106,1,Действия!$D$7:$D$106,"Продажи")=0,1,0))) -> 0 | AA10: =IF(A10="","",IF(OR(S10="",T10=""),"Нет данных",IF(AND(S10>0,T10<INT(Продажи!$D$4)),S10,0))) -> Нет данных | AB10: =IF(A10="","",IFERROR(VLOOKUP(F10,$A$111:$C$127,3,FALSE),"Не классифицировано")) -> Запрос / проверка | AC10: =IF(AND(A10<>"",V10<>"Закрыто",H10=""),1,0) -> 0 | AD10: 4800000
A11: С-102 | B11: Сделка | C11: Компания Д | D11: Менеджер 2 | E11: Прямые | F11: Расчёт | G11: 46315 | H11: 46319.75 | I11: Готово | J11: Нет | K11: Готово | L11: Готово | M11: Нет | N11: Нет | P11: Не требуется | Q11: Не требуется | V11: =IF(A11="","",IFERROR(VLOOKUP(F11,$A$111:$C$127,2,FALSE),"Не задан этап")) -> Согласованная калькуляция | W11: =IF(A11="","",IF(V11="Закрыто","",IF(OR(F11="Расчёт",F11="Решение об участии"),IF(COUNTIF(I11:M11,"Готово")+COUNTIF(I11:M11,"Не требуется")<5,IF(OR(I11="",I11="Нет"),"ТЗ; ","")&IF(OR(J11="",J11="Нет"),"КП завода; ","")&IF(OR(K11="",K11="Нет"),"логистика; ","")&IF(OR(L11="",L11="Нет"),"допрасходы; ","")&IF(OR(M11="",M11="Нет"),"цена продажи; ",""),IF(COUNTIF(I11:M11,"Не требуется")=5,"Проверить применимость расчёта",IF(AND(N11="Готово",O11<>""),"","Подтверждение калькуляции"))),IF(F11="Передача в исполнение",IF(AND(P11="Принято",O11<>""),"","Приём заказа смежниками"),IF(F11="Приёмка и оплата",IF(Q11<>"Принято","Подтверждение приёмки; ","")&IF(S11="","Остаток долга не загружен",IF(S11>0,"Оплата клиента","")),IF(AND(N11="Готово",O11<>""),"",V11)))))) -> КП завода; цена продажи; | X11: =IF(AND(A11<>"",V11<>"Закрыто",OR(Продажи!$I$4="Все",D11=Продажи!$I$4),OR(Продажи!$O$4="Все",E11=Продажи!$O$4)),1,0) -> 1 | Y11: =IF(A11="","",IF(AND(ISNUMBER(H11),H11<Продажи!$D$4,W11<>"",V11<>"Закрыто"),1,0)) -> 1 | Z11: =IF(A11="","",IF(V11="Закрыто",0,IF(COUNTIFS(Действия!$B$7:$B$106,A11,Действия!$N$7:$N$106,1,Действия!$D$7:$D$106,"Продажи")=0,1,0))) -> 1 | AA11: =IF(A11="","",IF(OR(S11="",T11=""),"Нет данных",IF(AND(S11>0,T11<INT(Продажи!$D$4)),S11,0))) -> Нет данных | AB11: =IF(A11="","",IFERROR(VLOOKUP(F11,$A$111:$C$127,3,FALSE),"Не классифицировано")) -> Расчёт / решение | AC11: =IF(AND(A11<>"",V11<>"Закрыто",H11=""),1,0) -> 0 | AD11: 12500000
A12: С-103 | B12: Сделка | C12: Компания Е | D12: Тендерный специалист | E12: Тендеры | F12: Решение об участии | G12: 46318 | H12: 46322.75 | I12: Готово | J12: Готово | K12: Нет | L12: Готово | M12: Нет | N12: Нет | P12: Не требуется | Q12: Не требуется | V12: =IF(A12="","",IFERROR(VLOOKUP(F12,$A$111:$C$127,2,FALSE),"Не задан этап")) -> Согласованная цена и решение участвовать | W12: =IF(A12="","",IF(V12="Закрыто","",IF(OR(F12="Расчёт",F12="Решение об участии"),IF(COUNTIF(I12:M12,"Готово")+COUNTIF(I12:M12,"Не требуется")<5,IF(OR(I12="",I12="Нет"),"ТЗ; ","")&IF(OR(J12="",J12="Нет"),"КП завода; ","")&IF(OR(K12="",K12="Нет"),"логистика; ","")&IF(OR(L12="",L12="Нет"),"допрасходы; ","")&IF(OR(M12="",M12="Нет"),"цена продажи; ",""),IF(COUNTIF(I12:M12,"Не требуется")=5,"Проверить применимость расчёта",IF(AND(N12="Готово",O12<>""),"","Подтверждение калькуляции"))),IF(F12="Передача в исполнение",IF(AND(P12="Принято",O12<>""),"","Приём заказа смежниками"),IF(F12="Приёмка и оплата",IF(Q12<>"Принято","Подтверждение приёмки; ","")&IF(S12="","Остаток долга не загружен",IF(S12>0,"Оплата клиента","")),IF(AND(N12="Готово",O12<>""),"",V12)))))) -> логистика; цена продажи; | X12: =IF(AND(A12<>"",V12<>"Закрыто",OR(Продажи!$I$4="Все",D12=Продажи!$I$4),OR(Продажи!$O$4="Все",E12=Продажи!$O$4)),1,0) -> 1 | Y12: =IF(A12="","",IF(AND(ISNUMBER(H12),H12<Продажи!$D$4,W12<>"",V12<>"Закрыто"),1,0)) -> 0 | Z12: =IF(A12="","",IF(V12="Закрыто",0,IF(COUNTIFS(Действия!$B$7:$B$106,A12,Действия!$N$7:$N$106,1,Действия!$D$7:$D$106,"Продажи")=0,1,0))) -> 0 | AA12: =IF(A12="","",IF(OR(S12="",T12=""),"Нет данных",IF(AND(S12>0,T12<INT(Продажи!$D$4)),S12,0))) -> Нет данных | AB12: =IF(A12="","",IFERROR(VLOOKUP(F12,$A$111:$C$127,3,FALSE),"Не классифицировано")) -> Расчёт / решение | AC12: =IF(AND(A12<>"",V12<>"Закрыто",H12=""),1,0) -> 0 | AD12: 28000000
A13: С-104 | B13: Сделка | C13: Компания Ж | D13: Менеджер 1 | E13: Прямые | F13: КП | G13: 46316 | H13: 46321.75 | I13: Не требуется | J13: Не требуется | K13: Не требуется | L13: Не требуется | M13: Не требуется | N13: Нет | P13: Не требуется | Q13: Не требуется | V13: =IF(A13="","",IFERROR(VLOOKUP(F13,$A$111:$C$127,2,FALSE),"Не задан этап")) -> Ответ клиента на предложение | W13: =IF(A13="","",IF(V13="Закрыто","",IF(OR(F13="Расчёт",F13="Решение об участии"),IF(COUNTIF(I13:M13,"Готово")+COUNTIF(I13:M13,"Не требуется")<5,IF(OR(I13="",I13="Нет"),"ТЗ; ","")&IF(OR(J13="",J13="Нет"),"КП завода; ","")&IF(OR(K13="",K13="Нет"),"логистика; ","")&IF(OR(L13="",L13="Нет"),"допрасходы; ","")&IF(OR(M13="",M13="Нет"),"цена продажи; ",""),IF(COUNTIF(I13:M13,"Не требуется")=5,"Проверить применимость расчёта",IF(AND(N13="Готово",O13<>""),"","Подтверждение калькуляции"))),IF(F13="Передача в исполнение",IF(AND(P13="Принято",O13<>""),"","Приём заказа смежниками"),IF(F13="Приёмка и оплата",IF(Q13<>"Принято","Подтверждение приёмки; ","")&IF(S13="","Остаток долга не загружен",IF(S13>0,"Оплата клиента","")),IF(AND(N13="Готово",O13<>""),"",V13)))))) -> Ответ клиента на предложение | X13: =IF(AND(A13<>"",V13<>"Закрыто",OR(Продажи!$I$4="Все",D13=Продажи!$I$4),OR(Продажи!$O$4="Все",E13=Продажи!$O$4)),1,0) -> 1 | Y13: =IF(A13="","",IF(AND(ISNUMBER(H13),H13<Продажи!$D$4,W13<>"",V13<>"Закрыто"),1,0)) -> 0 | Z13: =IF(A13="","",IF(V13="Закрыто",0,IF(COUNTIFS(Действия!$B$7:$B$106,A13,Действия!$N$7:$N$106,1,Действия!$D$7:$D$106,"Продажи")=0,1,0))) -> 0 | AA13: =IF(A13="","",IF(OR(S13="",T13=""),"Нет данных",IF(AND(S13>0,T13<INT(Продажи!$D$4)),S13,0))) -> Нет данных | AB13: =IF(A13="","",IFERROR(VLOOKUP(F13,$A$111:$C$127,3,FALSE),"Не классифицировано")) -> КП / подготовка | AC13: =IF(AND(A13<>"",V13<>"Закрыто",H13=""),1,0) -> 0 | AD13: 6750000
A14: С-105 | B14: Сделка | C14: Компания З | D14: Менеджер 2 | E14: Прямые | F14: КП | G14: 46314 | H14: 46318.75 | I14: Не требуется | J14: Не требуется | K14: Не требуется | L14: Не требуется | M14: Не требуется | N14: Нет | P14: Не требуется | Q14: Не требуется | V14: =IF(A14="","",IFERROR(VLOOKUP(F14,$A$111:$C$127,2,FALSE),"Не задан этап")) -> Ответ клиента на предложение | W14: =IF(A14="","",IF(V14="Закрыто","",IF(OR(F14="Расчёт",F14="Решение об участии"),IF(COUNTIF(I14:M14,"Готово")+COUNTIF(I14:M14,"Не требуется")<5,IF(OR(I14="",I14="Нет"),"ТЗ; ","")&IF(OR(J14="",J14="Нет"),"КП завода; ","")&IF(OR(K14="",K14="Нет"),"логистика; ","")&IF(OR(L14="",L14="Нет"),"допрасходы; ","")&IF(OR(M14="",M14="Нет"),"цена продажи; ",""),IF(COUNTIF(I14:M14,"Не требуется")=5,"Проверить применимость расчёта",IF(AND(N14="Готово",O14<>""),"","Подтверждение калькуляции"))),IF(F14="Передача в исполнение",IF(AND(P14="Принято",O14<>""),"","Приём заказа смежниками"),IF(F14="Приёмка и оплата",IF(Q14<>"Принято","Подтверждение приёмки; ","")&IF(S14="","Остаток долга не загружен",IF(S14>0,"Оплата клиента","")),IF(AND(N14="Готово",O14<>""),"",V14)))))) -> Ответ клиента на предложение | X14: =IF(AND(A14<>"",V14<>"Закрыто",OR(Продажи!$I$4="Все",D14=Продажи!$I$4),OR(Продажи!$O$4="Все",E14=Продажи!$O$4)),1,0) -> 1 | Y14: =IF(A14="","",IF(AND(ISNUMBER(H14),H14<Продажи!$D$4,W14<>"",V14<>"Закрыто"),1,0)) -> 1 | Z14: =IF(A14="","",IF(V14="Закрыто",0,IF(COUNTIFS(Действия!$B$7:$B$106,A14,Действия!$N$7:$N$106,1,Действия!$D$7:$D$106,"Продажи")=0,1,0))) -> 1 | AA14: =IF(A14="","",IF(OR(S14="",T14=""),"Нет данных",IF(AND(S14>0,T14<INT(Продажи!$D$4)),S14,0))) -> Нет данных | AB14: =IF(A14="","",IFERROR(VLOOKUP(F14,$A$111:$C$127,3,FALSE),"Не классифицировано")) -> КП / подготовка | AC14: =IF(AND(A14<>"",V14<>"Закрыто",H14=""),1,0) -> 0 | AD14: 3200000
A15: С-106 | B15: Сделка | C15: Компания И | D15: Менеджер 1 | E15: Прямые | F15: Переговоры | G15: 46317 | H15: 46322.75 | I15: Не требуется | J15: Не требуется | K15: Не требуется | L15: Не требуется | M15: Не требуется | N15: Готово | O15: Демо: протокол переговоров | P15: Не требуется | Q15: Не требуется | V15: =IF(A15="","",IFERROR(VLOOKUP(F15,$A$111:$C$127,2,FALSE),"Не задан этап")) -> Согласованные условия и открытые вопросы | W15: =IF(A15="","",IF(V15="Закрыто","",IF(OR(F15="Расчёт",F15="Решение об участии"),IF(COUNTIF(I15:M15,"Готово")+COUNTIF(I15:M15,"Не требуется")<5,IF(OR(I15="",I15="Нет"),"ТЗ; ","")&IF(OR(J15="",J15="Нет"),"КП завода; ","")&IF(OR(K15="",K15="Нет"),"логистика; ","")&IF(OR(L15="",L15="Нет"),"допрасходы; ","")&IF(OR(M15="",M15="Нет"),"цена продажи; ",""),IF(COUNTIF(I15:M15,"Не требуется")=5,"Проверить применимость расчёта",IF(AND(N15="Готово",O15<>""),"","Подтверждение калькуляции"))),IF(F15="Передача в исполнение",IF(AND(P15="Принято",O15<>""),"","Приём заказа смежниками"),IF(F15="Приёмка и оплата",IF(Q15<>"Принято","Подтверждение приёмки; ","")&IF(S15="","Остаток долга не загружен",IF(S15>0,"Оплата клиента","")),IF(AND(N15="Готово",O15<>""),"",V15)))))) | X15: =IF(AND(A15<>"",V15<>"Закрыто",OR(Продажи!$I$4="Все",D15=Продажи!$I$4),OR(Продажи!$O$4="Все",E15=Продажи!$O$4)),1,0) -> 1 | Y15: =IF(A15="","",IF(AND(ISNUMBER(H15),H15<Продажи!$D$4,W15<>"",V15<>"Закрыто"),1,0)) -> 0 | Z15: =IF(A15="","",IF(V15="Закрыто",0,IF(COUNTIFS(Действия!$B$7:$B$106,A15,Действия!$N$7:$N$106,1,Действия!$D$7:$D$106,"Продажи")=0,1,0))) -> 0 | AA15: =IF(A15="","",IF(OR(S15="",T15=""),"Нет данных",IF(AND(S15>0,T15<INT(Продажи!$D$4)),S15,0))) -> Нет данных | AB15: =IF(A15="","",IFERROR(VLOOKUP(F15,$A$111:$C$127,3,FALSE),"Не классифицировано")) -> Переговоры / подача | AC15: =IF(AND(A15<>"",V15<>"Закрыто",H15=""),1,0) -> 0 | AD15: 9400000
A16: С-107 | B16: Сделка | C16: Компания К | D16: Тендерный специалист | E16: Тендеры | F16: Дозапрос | G16: 46318 | H16: 46323.75 | I16: Не требуется | J16: Не требуется | K16: Не требуется | L16: Не требуется | M16: Не требуется | N16: Нет | P16: Не требуется | Q16: Не требуется | V16: =IF(A16="","",IFERROR(VLOOKUP(F16,$A$111:$C$127,2,FALSE),"Не задан этап")) -> Принятый площадкой ответ | W16: =IF(A16="","",IF(V16="Закрыто","",IF(OR(F16="Расчёт",F16="Решение об участии"),IF(COUNTIF(I16:M16,"Готово")+COUNTIF(I16:M16,"Не требуется")<5,IF(OR(I16="",I16="Нет"),"ТЗ; ","")&IF(OR(J16="",J16="Нет"),"КП завода; ","")&IF(OR(K16="",K16="Нет"),"логистика; ","")&IF(OR(L16="",L16="Нет"),"допрасходы; ","")&IF(OR(M16="",M16="Нет"),"цена продажи; ",""),IF(COUNTIF(I16:M16,"Не требуется")=5,"Проверить применимость расчёта",IF(AND(N16="Готово",O16<>""),"","Подтверждение калькуляции"))),IF(F16="Передача в исполнение",IF(AND(P16="Принято",O16<>""),"","Приём заказа смежниками"),IF(F16="Приёмка и оплата",IF(Q16<>"Принято","Подтверждение приёмки; ","")&IF(S16="","Остаток долга не загружен",IF(S16>0,"Оплата клиента","")),IF(AND(N16="Готово",O16<>""),"",V16)))))) -> Принятый площадкой ответ | X16: =IF(AND(A16<>"",V16<>"Закрыто",OR(Продажи!$I$4="Все",D16=Продажи!$I$4),OR(Продажи!$O$4="Все",E16=Продажи!$O$4)),1,0) -> 1 | Y16: =IF(A16="","",IF(AND(ISNUMBER(H16),H16<Продажи!$D$4,W16<>"",V16<>"Закрыто"),1,0)) -> 0 | Z16: =IF(A16="","",IF(V16="Закрыто",0,IF(COUNTIFS(Действия!$B$7:$B$106,A16,Действия!$N$7:$N$106,1,Действия!$D$7:$D$106,"Продажи")=0,1,0))) -> 0 | AA16: =IF(A16="","",IF(OR(S16="",T16=""),"Нет данных",IF(AND(S16>0,T16<INT(Продажи!$D$4)),S16,0))) -> Нет данных | AB16: =IF(A16="","",IFERROR(VLOOKUP(F16,$A$111:$C$127,3,FALSE),"Не классифицировано")) -> Переговоры / подача | AC16: =IF(AND(A16<>"",V16<>"Закрыто",H16=""),1,0) -> 0 | AD16: 41000000
A17: С-108 | B17: Сделка | C17: Компания Л | D17: Менеджер 2 | E17: Прямые | F17: Договор | G17: 46316 | H17: 46320.75 | I17: Не требуется | J17: Не требуется | K17: Не требуется | L17: Не требуется | M17: Не требуется | N17: Нет | P17: Не требуется | Q17: Не требуется | V17: =IF(A17="","",IFERROR(VLOOKUP(F17,$A$111:$C$127,2,FALSE),"Не задан этап")) -> Подписанные договор и спецификация | W17: =IF(A17="","",IF(V17="Закрыто","",IF(OR(F17="Расчёт",F17="Решение об участии"),IF(COUNTIF(I17:M17,"Готово")+COUNTIF(I17:M17,"Не требуется")<5,IF(OR(I17="",I17="Нет"),"ТЗ; ","")&IF(OR(J17="",J17="Нет"),"КП завода; ","")&IF(OR(K17="",K17="Нет"),"логистика; ","")&IF(OR(L17="",L17="Нет"),"допрасходы; ","")&IF(OR(M17="",M17="Нет"),"цена продажи; ",""),IF(COUNTIF(I17:M17,"Не требуется")=5,"Проверить применимость расчёта",IF(AND(N17="Готово",O17<>""),"","Подтверждение калькуляции"))),IF(F17="Передача в исполнение",IF(AND(P17="Принято",O17<>""),"","Приём заказа смежниками"),IF(F17="Приёмка и оплата",IF(Q17<>"Принято","Подтверждение приёмки; ","")&IF(S17="","Остаток долга не загружен",IF(S17>0,"Оплата клиента","")),IF(AND(N17="Готово",O17<>""),"",V17)))))) -> Подписанные договор и спецификация | X17: =IF(AND(A17<>"",V17<>"Закрыто",OR(Продажи!$I$4="Все",D17=Продажи!$I$4),OR(Продажи!$O$4="Все",E17=Продажи!$O$4)),1,0) -> 1 | Y17: =IF(A17="","",IF(AND(ISNUMBER(H17),H17<Продажи!$D$4,W17<>"",V17<>"Закрыто"),1,0)) -> 1 | Z17: =IF(A17="","",IF(V17="Закрыто",0,IF(COUNTIFS(Действия!$B$7:$B$106,A17,Действия!$N$7:$N$106,1,Действия!$D$7:$D$106,"Продажи")=0,1,0))) -> 1 | AA17: =IF(A17="","",IF(OR(S17="",T17=""),"Нет данных",IF(AND(S17>0,T17<INT(Продажи!$D$4)),S17,0))) -> Нет данных | AB17: =IF(A17="","",IFERROR(VLOOKUP(F17,$A$111:$C$127,3,FALSE),"Не классифицировано")) -> Договор / результат | AC17: =IF(AND(A17<>"",V17<>"Закрыто",H17=""),1,0) -> 0 | AD17: 8700000
A18: С-109 | B18: Сделка | C18: Компания М | D18: Тендерный специалист | E18: Тендеры | F18: Подготовка заявки | G18: 46319 | H18: 46323.75 | I18: Не требуется | J18: Не требуется | K18: Не требуется | L18: Не требуется | M18: Не требуется | N18: Готово | O18: Демо: комплект согласован | P18: Не требуется | Q18: Не требуется | V18: =IF(A18="","",IFERROR(VLOOKUP(F18,$A$111:$C$127,2,FALSE),"Не задан этап")) -> Полный комплект тендерной заявки | W18: =IF(A18="","",IF(V18="Закрыто","",IF(OR(F18="Расчёт",F18="Решение об участии"),IF(COUNTIF(I18:M18,"Готово")+COUNTIF(I18:M18,"Не требуется")<5,IF(OR(I18="",I18="Нет"),"ТЗ; ","")&IF(OR(J18="",J18="Нет"),"КП завода; ","")&IF(OR(K18="",K18="Нет"),"логистика; ","")&IF(OR(L18="",L18="Нет"),"допрасходы; ","")&IF(OR(M18="",M18="Нет"),"цена продажи; ",""),IF(COUNTIF(I18:M18,"Не требуется")=5,"Проверить применимость расчёта",IF(AND(N18="Готово",O18<>""),"","Подтверждение калькуляции"))),IF(F18="Передача в исполнение",IF(AND(P18="Принято",O18<>""),"","Приём заказа смежниками"),IF(F18="Приёмка и оплата",IF(Q18<>"Принято","Подтверждение приёмки; ","")&IF(S18="","Остаток долга не загружен",IF(S18>0,"Оплата клиента","")),IF(AND(N18="Готово",O18<>""),"",V18)))))) | X18: =IF(AND(A18<>"",V18<>"Закрыто",OR(Продажи!$I$4="Все",D18=Продажи!$I$4),OR(Продажи!$O$4="Все",E18=Продажи!$O$4)),1,0) -> 1 | Y18: =IF(A18="","",IF(AND(ISNUMBER(H18),H18<Продажи!$D$4,W18<>"",V18<>"Закрыто"),1,0)) -> 0 | Z18: =IF(A18="","",IF(V18="Закрыто",0,IF(COUNTIFS(Действия!$B$7:$B$106,A18,Действия!$N$7:$N$106,1,Действия!$D$7:$D$106,"Продажи")=0,1,0))) -> 0 | AA18: =IF(A18="","",IF(OR(S18="",T18=""),"Нет данных",IF(AND(S18>0,T18<INT(Продажи!$D$4)),S18,0))) -> Нет данных | AB18: =IF(A18="","",IFERROR(VLOOKUP(F18,$A$111:$C$127,3,FALSE),"Не классифицировано")) -> КП / подготовка | AC18: =IF(AND(A18<>"",V18<>"Закрыто",H18=""),1,0) -> 0 | AD18: 15500000
A19: И-201 | B19: Исполнение | C19: Компания Н / опоры | D19: Менеджер 1 | E19: Прямые | F19: Передача в исполнение | G19: 46319 | H19: 46321.5 | I19: Не требуется | J19: Не требуется | K19: Не требуется | L19: Не требуется | M19: Не требуется | N19: Нет | P19: Не принято | Q19: Не требуется | R19: Демо: ЗК-201 | V19: =IF(A19="","",IFERROR(VLOOKUP(F19,$A$111:$C$127,2,FALSE),"Не задан этап")) -> Заказ принят снабжением и логистикой | W19: =IF(A19="","",IF(V19="Закрыто","",IF(OR(F19="Расчёт",F19="Решение об участии"),IF(COUNTIF(I19:M19,"Готово")+COUNTIF(I19:M19,"Не требуется")<5,IF(OR(I19="",I19="Нет"),"ТЗ; ","")&IF(OR(J19="",J19="Нет"),"КП завода; ","")&IF(OR(K19="",K19="Нет"),"логистика; ","")&IF(OR(L19="",L19="Нет"),"допрасходы; ","")&IF(OR(M19="",M19="Нет"),"цена продажи; ",""),IF(COUNTIF(I19:M19,"Не требуется")=5,"Проверить применимость расчёта",IF(AND(N19="Готово",O19<>""),"","Подтверждение калькуляции"))),IF(F19="Передача в исполнение",IF(AND(P19="Принято",O19<>""),"","Приём заказа смежниками"),IF(F19="Приёмка и оплата",IF(Q19<>"Принято","Подтверждение приёмки; ","")&IF(S19="","Остаток долга не загружен",IF(S19>0,"Оплата клиента","")),IF(AND(N19="Готово",O19<>""),"",V19)))))) -> Приём заказа смежниками | X19: =IF(AND(A19<>"",V19<>"Закрыто",OR(Продажи!$I$4="Все",D19=Продажи!$I$4),OR(Продажи!$O$4="Все",E19=Продажи!$O$4)),1,0) -> 1 | Y19: =IF(A19="","",IF(AND(ISNUMBER(H19),H19<Продажи!$D$4,W19<>"",V19<>"Закрыто"),1,0)) -> 0 | Z19: =IF(A19="","",IF(V19="Закрыто",0,IF(COUNTIFS(Действия!$B$7:$B$106,A19,Действия!$N$7:$N$106,1,Действия!$D$7:$D$106,"Продажи")=0,1,0))) -> 1 | AA19: =IF(A19="","",IF(OR(S19="",T19=""),"Нет данных",IF(AND(S19>0,T19<INT(Продажи!$D$4)),S19,0))) -> Нет данных | AB19: =IF(A19="","",IFERROR(VLOOKUP(F19,$A$111:$C$127,3,FALSE),"Не классифицировано")) -> Передача / исполнение | AC19: =IF(AND(A19<>"",V19<>"Закрыто",H19=""),1,0) -> 0
